Workbook

Sheet 1
A1: وزارة الصحة والسكان | AB1: وزارة الصحة والسكان | AW1: وزارة الصحة والسكان
A2: قطاع الطب الوقائي والصحة العامة | AB2: قطاع الطب الوقائي والصحة العامة | AW2: قطاع الطب الوقائي والصحة العامة
A3: الإدارة المركزية للصحة العامة | AB3: الإدارة المركزية للصحة العامة | AW3: الإدارة المركزية للصحة العامة
A4: الإدارة العامة لمكافحة الأمراض المعدية | AB4: الإدارة العامة لمكافحة الأمراض المعدية | AW4: الإدارة العامة لمكافحة الأمراض المعدية
A5: البرنامج الموسع للتطعيمات | AB5: البرنامج الموسع للتطعيمات | AW5: البرنامج الموسع للتطعيمات
A6: بيان باعداد المتطعمين و المتغيبين و الاثار الجانبية بالحملة القومية للتطعيم بطعم MR | AF6: البلاغ اليومى لحركة الطعوم بالحملة القومية للتطعيم بطعم MR | AY6: بيان المدارس و الحضانات بالحملة القومية للتطعيم بطعم MR
A7: مديرية الشئون الصحية / المنوفية الإدارة الصحية / قويسنا التاريخ / 25/10/2026 اليوم / الاحد | AJ7: مديرية الشئون الصحية / الإدارة الصحية / التاريخ/ اليوم / | BC7: مديرية الشئون الصحية / الإدارة الصحية / التاريخ/ اليوم /
A8: م | B8: اسم الوحدة/ مكتب الصحة | C8: المستهدف | D8: عدد الفرق | E8: المتطعمين المصريين | K8: المتطعمين غير المصريين | Q8: الاجمالى | S8: النسبة | T8: المتغيبين عن التطعيم | V8: المطعمين من المتغيبين | X8: الاثار الجانبية | AB8: م | AC8: اسم الوحدة | AD8: الرصيد اول اليوم | AE8: عدد الزجاجات الواردة | AG8: عدد الزجاجات المستهلكة | AI8: عدد الزجاجات المتبقية | AJ8: معدل الزجاجة اليوم | AK8: معدل الزجاجة حتي اليوم | AM8: مخزن طعوم الادارة | AN8: التشغيلة | AO8: الرصيد اول اليوم | AP8: عدد الزجاجات الواردة | AR8: عدد الزجاجات المنصرفة | AT8: عدد الزجاجات المتبقية | AW8: اسم الوحدة | AX8: بيان المدارس | BD8: بيان الحضانات
E9: من 9 شهور لأقل من عام | G9: من عام لأقل من5 سنوات | I9: من 5 سنوات الى 10 سنة | K9: من 9 شهور لأقل من عام | M9: من عام لأقل من5 سنوات | O9: من 5 سنوات الى 10 سنة | AP9: اليوم | AQ9: حتى اليوم | AR9: اليوم | AS9: حتى اليوم | AX9: عدد المدارس | AY9: المستهدف | AZ9: عدد المدارس التي تم زيارتها حتى اليوم | BA9: عدد المتطعمين اليوم | BB9: عدد المتطعمين حتى اليوم | BC9: النسبة | BD9: عدد الحضانات | BE9: المستهدف | BF9: عدد الحضانات التي تم زيارتها حتى اليوم | BG9: عدد المتطعمين اليوم | BH9: عدد المتطعمين حتى اليوم | BI9: النسبة
E10: اليوم | F10: حتى اليوم | G10: اليوم | H10: حتى اليوم | I10: اليوم | J10: حتى اليوم | K10: اليوم | L10: حتى اليوم | M10: اليوم | N10: حتى اليوم | O10: اليوم | P10: حتى اليوم | Q10: اليوم | R10: حتى اليوم | T10: اليوم | U10: حتى اليوم | V10: اليوم | W10: حتى اليوم | X10: اليوم | Y10: حتى اليوم | AE10: اليوم | AF10: حتى اليوم | AG10: اليوم | AH10: حتى اليوم | AN10: 0124W120 | AO10: 73 | AP10: 0 | AQ10: =AO10+AP10 -> 73 | AR10: 0 | AS10: =AR10 -> 0 | AT10: =AO10+AP10-AR10 -> 73
A11: 1 | B11: مكتب الصحة | C11: 12251 | D11: 13 | E11: 11 | F11: =E11 -> 11 | G11: 417 | H11: =G11 -> 417 | I11: 2013 | J11: =I11 -> 2013 | K11: 0 | L11: =K11 -> 0 | M11: 0 | N11: =M11 -> 0 | O11: 0 | P11: =O11 -> 0 | Q11: =O11+M11+K11+I11+G11+E11 -> 2441 | R11: =Q11 -> 2441 | S11: =R11/C11 -> 0.19924904 | T11: 402 | U11: =T11 -> 402 | V11: 0 | W11: =V11 -> 0 | X11: 0 | Y11: =X11 -> 0 | AB11: 1 | AC11: =AW11 -> مكتب الصحة | AD11: 1076 | AE11: 0 | AF11: =AD11+AE11 -> 1076 | AG11: 249 | AH11: =AG11 -> 249 | AI11: =AD11+AE11-AG11 -> 827 | AJ11: =Q11/AG11 -> 9.8032129 | AK11: =R11/AH11 -> 9.8032129 | AN11: 420604325A | AO11: 8550 | AP11: 0 | AQ11: =AO11+AP11 -> 8550 | AR11: 2120 | AS11: =AR11 -> 2120 | AT11: =AO11+AP11-AR11 -> 6430 | AW11: =B11 -> مكتب الصحة | AX11: 11 | AY11: 8411 | AZ11: 4 | BA11: 2251 | BB11: =BA11 -> 2251 | BC11: =BB11/AY11 -> 0.26762573 | BD11: 27 | BE11: 1746 | BF11: 0 | BG11: 0 | BH11: =BG11 -> 0 | BI11: =BH11/BE11 -> 0
A12: 2 | B12: شبرابخـــــــــــوم | C12: 4445 | D12: 4 | E12: 1 | F12: =E12 -> 1 | G12: 25 | H12: =G12 -> 25 | I12: 652 | J12: =I12 -> 652 | K12: 0 | L12: =K12 -> 0 | M12: 0 | N12: =M12 -> 0 | O12: 0 | P12: =O12 -> 0 | Q12: =O12+M12+K12+I12+G12+E12 -> 678 | R12: =Q12 -> 678 | S12: =R12/C12 -> 0.15253093 | T12: 102 | U12: =T12 -> 102 | V12: 1 | W12: =V12 -> 1 | X12: 0 | Y12: =X12 -> 0 | AB12: 2 | AC12: =AW12 -> شبرابخـــــــــــوم | AD12: 390 | AE12: 0 | AF12: =AD12+AE12 -> 390 | AG12: 70 | AH12: =AG12 -> 70 | AI12: =AD12+AE12-AG12 -> 320 | AJ12: =Q12/AG12 -> 9.6857143 | AK12: =R12/AH12 -> 9.6857143 | AQ12: =AO12+AP12 -> 0 | AS12: =AR12 -> 0 | AT12: =AO12+AP12-AR12 -> 0 | AW12: =B12 -> شبرابخـــــــــــوم | AX12: 6 | AY12: 2215 | AZ12: 2 | BA12: 678 | BB12: =BA12 -> 678 | BC12: =BB12/AY12 -> 0.30609481 | BD12: 16 | BE12: 729 | BF12: 0 | BG12: 0 | BH12: =BG12 -> 0 | BI12: =BH12/BE12 -> 0
A13: 3 | B13: ميت بره | C13: 11614 | D13: 8 | E13: 13 | F13: =E13 -> 13 | G13: 45 | H13: =G13 -> 45 | I13: 1545 | J13: =I13 -> 1545 | K13: 0 | L13: =K13 -> 0 | M13: 0 | N13: =M13 -> 0 | O13: 0 | P13: =O13 -> 0 | Q13: =O13+M13+K13+I13+G13+E13 -> 1603 | R13: =Q13 -> 1603 | S13: =R13/C13 -> 0.13802308 | T13: 199 | U13: =T13 -> 199 | V13: 0 | W13: =V13 -> 0 | X13: 0 | Y13: =X13 -> 0 | AB13: 3 | AC13: =AW13 -> ميت بره | AD13: 1020 | AE13: 0 | AF13: =AD13+AE13 -> 1020 | AG13: 163 | AH13: =AG13 -> 163 | AI13: =AD13+AE13-AG13 -> 857 | AJ13: =Q13/AG13 -> 9.8343558 | AK13: =R13/AH13 -> 9.8343558 | AN13: اجمالي المخزن | AO13: =SUM(AO10:AO12) -> 8623 | AP13: =SUM(AP10:AP12) -> 0 | AQ13: =SUM(AQ10:AQ12) -> 8623 | AR13: =SUM(AR10:AR12) -> 2120 | AS13: =SUM(AS10:AS12) -> 2120 | AT13: =SUM(AT10:AT12) -> 6503 | AW13: =B13 -> ميت بره | AX13: 8 | AY13: 4849 | AZ13: 3 | BA13: 1533 | BB13: =BA13 -> 1533 | BC13: =BB13/AY13 -> 0.31614766 | BD13: 21 | BE13: 1129 | BF13: 0 | BG13: 0 | BH13: =BG13 -> 0 | BI13: =BH13/BE13 -> 0
A14: 4 | B14: أبنــــــــــــــــهس | C14: 5029 | D14: 4 | E14: 4 | F14: =E14 -> 4 | G14: 29 | H14: =G14 -> 29 | I14: 886 | J14: =I14 -> 886 | K14: 0 | L14: =K14 -> 0 | M14: 0 | N14: =M14 -> 0 | O14: 0 | P14: =O14 -> 0 | Q14: =O14+M14+K14+I14+G14+E14 -> 919 | R14: =Q14 -> 919 | S14: =R14/C14 -> 0.18274011 | T14: 77 | U14: =T14 -> 77 | V14: 0 | W14: =V14 -> 0 | X14: 0 | Y14: =X14 -> 0 | AB14: 4 | AC14: =AW14 -> أبنــــــــــــــــهس | AD14: 440 | AE14: 0 | AF14: =AD14+AE14 -> 440 | AG14: 94 | AH14: =AG14 -> 94 | AI14: =AD14+AE14-AG14 -> 346 | AJ14: =Q14/AG14 -> 9.7765957 | AK14: =R14/AH14 -> 9.7765957 | AM14: احمالي الوحدات ومخزن الادارة | AT14: =AT13+AI51 -> 12933 | AW14: =B14 -> أبنــــــــــــــــهس | AX14: 7 | AY14: 2531 | AZ14: 3 | BA14: 919 | BB14: =BA14 -> 919 | BC14: =BB14/AY14 -> 0.36309759 | BD14: 23 | BE14: 921 | BF14: 0 | BG14: 0 | BH14: =BG14 -> 0 | BI14: =BH14/BE14 -> 0
A15: 5 | B15: ميت ســـــــــراج | C15: 2369 | D15: 3 | E15: 1 | F15: =E15 -> 1 | G15: 182 | H15: =G15 -> 182 | I15: 265 | J15: =I15 -> 265 | K15: 0 | L15: =K15 -> 0 | M15: 0 | N15: =M15 -> 0 | O15: 0 | P15: =O15 -> 0 | Q15: =O15+M15+K15+I15+G15+E15 -> 448 | R15: =Q15 -> 448 | S15: =R15/C15 -> 0.18910933 | T15: 49 | U15: =T15 -> 49 | V15: 0 | W15: =V15 -> 0 | X15: 0 | Y15: =X15 -> 0 | AB15: 5 | AC15: =AW15 -> ميت ســـــــــراج | AD15: 209 | AE15: 0 | AF15: =AD15+AE15 -> 209 | AG15: 46 | AH15: =AG15 -> 46 | AI15: =AD15+AE15-AG15 -> 163 | AJ15: =Q15/AG15 -> 9.7391304 | AK15: =R15/AH15 -> 9.7391304 | AW15: =B15 -> ميت ســـــــــراج | AX15: 2 | AY15: 1041 | AZ15: 1 | BA15: 307 | BB15: =BA15 -> 307 | BC15: =BB15/AY15 -> 0.29490874 | BD15: 5 | BE15: 310 | BF15: 3 | BG15: 141 | BH15: =BG15 -> 141 | BI15: =BH15/BE15 -> 0.45483871
A16: 6 | B16: أم خــــــــــــــنان | C16: 4900 | D16: 4 | E16: 3 | F16: =E16 -> 3 | G16: 121 | H16: =G16 -> 121 | I16: 669 | J16: =I16 -> 669 | K16: 0 | L16: =K16 -> 0 | M16: 0 | N16: =M16 -> 0 | O16: 0 | P16: =O16 -> 0 | Q16: =O16+M16+K16+I16+G16+E16 -> 793 | R16: =Q16 -> 793 | S16: =R16/C16 -> 0.16183673 | T16: 114 | U16: =T16 -> 114 | V16: 0 | W16: =V16 -> 0 | X16: 0 | Y16: =X16 -> 0 | AB16: 6 | AC16: =AW16 -> أم خــــــــــــــنان | AD16: 430 | AE16: 0 | AF16: =AD16+AE16 -> 430 | AG16: 80 | AH16: =AG16 -> 80 | AI16: =AD16+AE16-AG16 -> 350 | AJ16: =Q16/AG16 -> 9.9125 | AK16: =R16/AH16 -> 9.9125 | AW16: =B16 -> أم خــــــــــــــنان | AX16: 8 | AY16: 2981 | AZ16: 1 | BA16: 764 | BB16: =BA16 -> 764 | BC16: =BB16/AY16 -> 0.25628984 | BD16: 12 | BE16: 1313 | BF16: 0 | BG16: 0 | BH16: =BG16 -> 0 | BI16: =BH16/BE16 -> 0
A17: 7 | B17: أجهور الرمل | C17: 3590 | D17: 3 | E17: 1 | F17: =E17 -> 1 | G17: 210 | H17: =G17 -> 210 | I17: 629 | J17: =I17 -> 629 | K17: 0 | L17: =K17 -> 0 | M17: 0 | N17: =M17 -> 0 | O17: 0 | P17: =O17 -> 0 | Q17: =O17+M17+K17+I17+G17+E17 -> 840 | R17: =Q17 -> 840 | S17: =R17/C17 -> 0.23398329 | T17: 161 | U17: =T17 -> 161 | V17: 0 | W17: =V17 -> 0 | X17: 0 | Y17: =X17 -> 0 | AB17: 7 | AC17: =AW17 -> أجهور الرمل | AD17: 316 | AE17: 0 | AF17: =AD17+AE17 -> 316 | AG17: 86 | AH17: =AG17 -> 86 | AI17: =AD17+AE17-AG17 -> 230 | AJ17: =Q17/AG17 -> 9.7674419 | AK17: =R17/AH17 -> 9.7674419 | AW17: =B17 -> أجهور الرمل | AX17: 4 | AY17: 1796 | AZ17: 1 | BA17: 598 | BB17: =BA17 -> 598 | BC17: =BB17/AY17 -> 0.33296214 | BD17: 3 | BE17: 100 | BF17: 2 | BG17: 242 | BH17: =BG17 -> 242 | BI17: =BH17/BE17 -> 2.42
A18: 8 | B18: منشأة دمــــــــــلو | C18: 1320 | D18: 2 | E18: 11 | F18: =E18 -> 11 | G18: 98 | H18: =G18 -> 98 | I18: 502 | J18: =I18 -> 502 | K18: 0 | L18: =K18 -> 0 | M18: 0 | N18: =M18 -> 0 | O18: 0 | P18: =O18 -> 0 | Q18: =O18+M18+K18+I18+G18+E18 -> 611 | R18: =Q18 -> 611 | S18: =R18/C18 -> 0.46287879 | T18: 91 | U18: =T18 -> 91 | V18: 8 | W18: =V18 -> 8 | X18: 0 | Y18: =X18 -> 0 | AB18: 8 | AC18: =AW18 -> منشأة دمــــــــــلو | AD18: 115 | AE18: 0 | AF18: =AD18+AE18 -> 115 | AG18: 63 | AH18: =AG18 -> 63 | AI18: =AD18+AE18-AG18 -> 52 | AJ18: =Q18/AG18 -> 9.6984127 | AK18: =R18/AH18 -> 9.6984127 | AW18: =B18 -> منشأة دمــــــــــلو | AX18: 2 | AY18: 896 | AZ18: 1 | BA18: 561 | BB18: =BA18 -> 561 | BC18: =BB18/AY18 -> 0.62611607 | BD18: 8 | BE18: 340 | BF18: 1 | BG18: 0 | BH18: =BG18 -> 0 | BI18: =BH18/BE18 -> 0
A19: 9 | B19: شـــــــــــــرانيس | C19: 1414 | D19: 2 | E19: 7 | F19: =E19 -> 7 | G19: 14 | H19: =G19 -> 14 | I19: 424 | J19: =I19 -> 424 | K19: 0 | L19: =K19 -> 0 | M19: 0 | N19: =M19 -> 0 | O19: 0 | P19: =O19 -> 0 | Q19: =O19+M19+K19+I19+G19+E19 -> 445 | R19: =Q19 -> 445 | S19: =R19/C19 -> 0.31471004 | T19: 46 | U19: =T19 -> 46 | V19: 0 | W19: =V19 -> 0 | X19: 0 | Y19: =X19 -> 0 | AB19: 9 | AC19: =AW19 -> شـــــــــــــرانيس | AD19: 125 | AE19: 0 | AF19: =AD19+AE19 -> 125 | AG19: 46 | AH19: =AG19 -> 46 | AI19: =AD19+AE19-AG19 -> 79 | AJ19: =Q19/AG19 -> 9.673913 | AK19: =R19/AH19 -> 9.673913 | AW19: =B19 -> شـــــــــــــرانيس | AX19: 2 | AY19: 675 | AZ19: 1 | BA19: 427 | BB19: =BA19 -> 427 | BC19: =BB19/AY19 -> 0.63259259 | BD19: 2 | BE19: 397 | BF19: 0 | BG19: 0 | BH19: =BG19 -> 0 | BI19: =BH19/BE19 -> 0
A20: 10 | B20: قويســـــــــنا البلد | C20: 4115 | D20: 3 | E20: 14 | F20: =E20 -> 14 | G20: 32 | H20: =G20 -> 32 | I20: 527 | J20: =I20 -> 527 | K20: 0 | L20: =K20 -> 0 | M20: 0 | N20: =M20 -> 0 | O20: 0 | P20: =O20 -> 0 | Q20: =O20+M20+K20+I20+G20+E20 -> 573 | R20: =Q20 -> 573 | S20: =R20/C20 -> 0.13924666 | T20: 154 | U20: =T20 -> 154 | V20: 0 | W20: =V20 -> 0 | X20: 0 | Y20: =X20 -> 0 | AB20: 10 | AC20: =AW20 -> قويســـــــــنا البلد | AD20: 360 | AE20: 0 | AF20: =AD20+AE20 -> 360 | AG20: 58 | AH20: =AG20 -> 58 | AI20: =AD20+AE20-AG20 -> 302 | AJ20: =Q20/AG20 -> 9.8793103 | AK20: =R20/AH20 -> 9.8793103 | AW20: =B20 -> قويســـــــــنا البلد | AX20: 2 | AY20: 1539 | AZ20: 1 | BA20: 523 | BB20: =BA20 -> 523 | BC20: =BB20/AY20 -> 0.33983106 | BD20: 7 | BE20: 580 | BF20: 0 | BG20: 0 | BH20: =BG20 -> 0 | BI20: =BH20/BE20 -> 0
A21: 11 | B21: بجيرم | C21: 1782 | D21: 3 | E21: 5 | F21: =E21 -> 5 | G21: 101 | H21: =G21 -> 101 | I21: 405 | J21: =I21 -> 405 | K21: 0 | L21: =K21 -> 0 | M21: 0 | N21: =M21 -> 0 | O21: 0 | P21: =O21 -> 0 | Q21: =O21+M21+K21+I21+G21+E21 -> 511 | R21: =Q21 -> 511 | S21: =R21/C21 -> 0.28675645 | T21: 56 | U21: =T21 -> 56 | V21: 0 | W21: =V21 -> 0 | X21: 0 | Y21: =X21 -> 0 | AB21: 11 | AC21: =AW21 -> بجيرم | AD21: 157 | AE21: 0 | AF21: =AD21+AE21 -> 157 | AG21: 52 | AH21: =AG21 -> 52 | AI21: =AD21+AE21-AG21 -> 105 | AJ21: =Q21/AG21 -> 9.8269231 | AK21: =R21/AH21 -> 9.8269231 | AW21: =B21 -> بجيرم | AX21: 4 | AY21: 946 | AZ21: 1 | BA21: 460 | BB21: =BA21 -> 460 | BC21: =BB21/AY21 -> 0.48625793 | BD21: 4 | BE21: 99 | BF21: 0 | BG21: 0 | BH21: =BG21 -> 0 | BI21: =BH21/BE21 -> 0
A22: 12 | B22: كفر بنى غريـــان | C22: 2184 | D22: 3 | E22: 3 | F22: =E22 -> 3 | G22: 181 | H22: =G22 -> 181 | I22: 442 | J22: =I22 -> 442 | K22: 0 | L22: =K22 -> 0 | M22: 0 | N22: =M22 -> 0 | O22: 0 | P22: =O22 -> 0 | Q22: =O22+M22+K22+I22+G22+E22 -> 626 | R22: =Q22 -> 626 | S22: =R22/C22 -> 0.28663004 | T22: 68 | U22: =T22 -> 68 | V22: 0 | W22: =V22 -> 0 | X22: 0 | Y22: =X22 -> 0 | AB22: 12 | AC22: =AW22 -> كفر بنى غريـــان | AD22: 192 | AE22: 0 | AF22: =AD22+AE22 -> 192 | AG22: 63 | AH22: =AG22 -> 63 | AI22: =AD22+AE22-AG22 -> 129 | AJ22: =Q22/AG22 -> 9.9365079 | AK22: =R22/AH22 -> 9.9365079 | AW22: =B22 -> كفر بنى غريـــان | AX22: 3 | AY22: 1327 | AZ22: 1 | BA22: 566 | BB22: =BA22 -> 566 | BC22: =BB22/AY22 -> 0.426526 | BD22: 9 | BE22: 381 | BF22: 1 | BG22: 134 | BH22: =BG22 -> 134 | BI22: =BH22/BE22 -> 0.35170604
A23: 13 | B23: بــقســـــــــــــــــا | C23: 862 | D23: 2 | E23: 4 | F23: =E23 -> 4 | G23: 38 | H23: =G23 -> 38 | I23: 326 | J23: =I23 -> 326 | K23: 0 | L23: =K23 -> 0 | M23: 0 | N23: =M23 -> 0 | O23: 0 | P23: =O23 -> 0 | Q23: =O23+M23+K23+I23+G23+E23 -> 368 | R23: =Q23 -> 368 | S23: =R23/C23 -> 0.42691415 | T23: 27 | U23: =T23 -> 27 | V23: 5 | W23: =V23 -> 5 | X23: 0 | Y23: =X23 -> 0 | AB23: 13 | AC23: =AW23 -> بــقســـــــــــــــــا | AD23: 75 | AE23: 0 | AF23: =AD23+AE23 -> 75 | AG23: 37 | AH23: =AG23 -> 37 | AI23: =AD23+AE23-AG23 -> 38 | AJ23: =Q23/AG23 -> 9.9459459 | AK23: =R23/AH23 -> 9.9459459 | AW23: =B23 -> بــقســـــــــــــــــا | AX23: 1 | AY23: 311 | AZ23: 1 | BA23: 288 | BB23: =BA23 -> 288 | BC23: =BB23/AY23 -> 0.92604502 | BD23: 1 | BE23: 40 | BF23: 0 | BG23: 0 | BH23: =BG23 -> 0 | BI23: =BH23/BE23 -> 0
A24: 14 | B24: كفــــــــر الأكرم | C24: 918 | D24: 2 | E24: 0 | F24: =E24 -> 0 | G24: 62 | H24: =G24 -> 62 | I24: 185 | J24: =I24 -> 185 | K24: 0 | L24: =K24 -> 0 | M24: 0 | N24: =M24 -> 0 | O24: 0 | P24: =O24 -> 0 | Q24: =O24+M24+K24+I24+G24+E24 -> 247 | R24: =Q24 -> 247 | S24: =R24/C24 -> 0.26906318 | T24: 36 | U24: =T24 -> 36 | V24: 0 | W24: =V24 -> 0 | X24: 0 | Y24: =X24 -> 0 | AB24: 14 | AC24: =AW24 -> كفــــــــر الأكرم | AD24: 80 | AE24: 0 | AF24: =AD24+AE24 -> 80 | AG24: 25 | AH24: =AG24 -> 25 | AI24: =AD24+AE24-AG24 -> 55 | AJ24: =Q24/AG24 -> 9.88 | AK24: =R24/AH24 -> 9.88 | AW24: =B24 -> كفــــــــر الأكرم | AX24: 2 | AY24: 540 | AZ24: 1 | BA24: 185 | BB24: =BA24 -> 185 | BC24: =BB24/AY24 -> 0.34259259 | BD24: 2 | BE24: 115 | BF24: 1 | BG24: 32 | BH24: =BG24 -> 32 | BI24: =BH24/BE24 -> 0.27826087
A25: 15 | B25: كفـــــــــر إبنهس | C25: 2072 | D25: 3 | E25: 0 | F25: =E25 -> 0 | G25: 4 | H25: =G25 -> 4 | I25: 605 | J25: =I25 -> 605 | K25: 0 | L25: =K25 -> 0 | M25: 0 | N25: =M25 -> 0 | O25: 0 | P25: =O25 -> 0 | Q25: =O25+M25+K25+I25+G25+E25 -> 609 | R25: =Q25 -> 609 | S25: =R25/C25 -> 0.29391892 | T25: 108 | U25: =T25 -> 108 | V25: 0 | W25: =V25 -> 0 | X25: 0 | Y25: =X25 -> 0 | AB25: 15 | AC25: =AW25 -> كفـــــــــر إبنهس | AD25: 180 | AE25: 0 | AF25: =AD25+AE25 -> 180 | AG25: 76 | AH25: =AG25 -> 76 | AI25: =AD25+AE25-AG25 -> 104 | AJ25: =Q25/AG25 -> 8.0131579 | AK25: =R25/AH25 -> 8.0131579 | AW25: =B25 -> كفـــــــــر إبنهس | AX25: 3 | AY25: 1013 | AZ25: 3 | BA25: 602 | BB25: =BA25 -> 602 | BC25: =BB25/AY25 -> 0.59427443 | BD25: 4 | BE25: 620 | BF25: 0 | BG25: 0 | BH25: =BG25 -> 0 | BI25: =BH25/BE25 -> 0
A26: 16 | B26: الرمــــــــــــــالى | C26: 2699 | D26: 3 | E26: 5 | F26: =E26 -> 5 | G26: 133 | H26: =G26 -> 133 | I26: 341 | J26: =I26 -> 341 | K26: 0 | L26: =K26 -> 0 | M26: 0 | N26: =M26 -> 0 | O26: 0 | P26: =O26 -> 0 | Q26: =O26+M26+K26+I26+G26+E26 -> 479 | R26: =Q26 -> 479 | S26: =R26/C26 -> 0.17747314 | T26: 36 | U26: =T26 -> 36 | V26: 0 | W26: =V26 -> 0 | X26: 1 | Y26: =X26 -> 1 | AB26: 16 | AC26: =AW26 -> الرمــــــــــــــالى | AD26: 235 | AE26: 0 | AF26: =AD26+AE26 -> 235 | AG26: 49 | AH26: =AG26 -> 49 | AI26: =AD26+AE26-AG26 -> 186 | AJ26: =Q26/AG26 -> 9.7755102 | AK26: =R26/AH26 -> 9.7755102 | AW26: =B26 -> الرمــــــــــــــالى | AX26: 3 | AY26: 1486 | AZ26: 1 | BA26: 425 | BB26: =BA26 -> 425 | BC26: =BB26/AY26 -> 0.28600269 | BD26: 3 | BE26: 98 | BF26: 0 | BG26: 0 | BH26: =BG26 -> 0 | BI26: =BH26/BE26 -> 0
... A44: 34 | B44: منشأة أم خنان | C44: 510 | D44: 2 | E44: 6 | F44: =E44 -> 6 | G44: 25 | H44: =G44 -> 25 | I44: 276 | J44: =I44 -> 276 | K44: 0 | L44: =K44 -> 0 | M44: 0 | N44: =M44 -> 0 | O44: 0 | P44: =O44 -> 0 | Q44: =O44+M44+K44+I44+G44+E44 -> 307 | R44: =Q44 -> 307 | S44: =R44/C44 -> 0.60196078 | T44: 7 | U44: =T44 -> 7 | V44: 1 | W44: =V44 -> 1 | X44: 0 | Y44: =X44 -> 0 | AB44: 34 | AC44: =AW44 -> منشأة أم خنان | AD44: 45 | AE44: 0 | AF44: =AD44+AE44 -> 45 | AG44: 31 | AH44: =AG44 -> 31 | AI44: =AD44+AE44-AG44 -> 14 | AJ44: =Q44/AG44 -> 9.9032258 | AK44: =R44/AH44 -> 9.9032258 | AW44: =B44 -> منشأة أم خنان | AX44: 1 | AY44: 277 | AZ44: 1 | BA44: 269 | BB44: =BA44 -> 269 | BC44: =BB44/AY44 -> 0.97111913 | BD44: 3 | BE44: 170 | BF44: 0 | BG44: 0 | BH44: =BG44 -> 0 | BI44: =BH44/BE44 -> 0
A45: 35 | F45: =E45 -> 0 | H45: =G45 -> 0 | J45: =I45 -> 0 | L45: =K45 -> 0 | N45: =M45 -> 0 | P45: =O45 -> 0 | Q45: =O45+M45+K45+I45+G45+E45 -> 0 | R45: =Q45 -> 0 | S45: =R45/C45 -> #DIV/0! | U45: =T45 -> 0 | W45: =V45 -> 0 | Y45: =X45 -> 0 | AB45: 35 | AC45: =AW45 -> 0 | AF45: =AD45+AE45 -> 0 | AH45: =AG45 -> 0 | AI45: =AD45+AE45-AG45 -> 0 | AJ45: =Q45/AG45 -> #DIV/0! | AK45: =R45/AH45 -> #DIV/0! | AW45: =B45 -> 0 | BB45: =BA45 -> 0 | BC45: =BB45/AY45 -> #DIV/0! | BH45: =BG45 -> 0 | BI45: =BH45/BE45 -> #DIV/0!
A46: 36 | F46: =E46 -> 0 | H46: =G46 -> 0 | J46: =I46 -> 0 | L46: =K46 -> 0 | N46: =M46 -> 0 | P46: =O46 -> 0 | Q46: =O46+M46+K46+I46+G46+E46 -> 0 | R46: =Q46 -> 0 | S46: =R46/C46 -> #DIV/0! | U46: =T46 -> 0 | W46: =V46 -> 0 | Y46: =X46 -> 0 | AB46: 36 | AC46: =AW46 -> 0 | AF46: =AD46+AE46 -> 0 | AH46: =AG46 -> 0 | AI46: =AD46+AE46-AG46 -> 0 | AJ46: =Q46/AG46 -> #DIV/0! | AK46: =R46/AH46 -> #DIV/0! | AW46: =B46 -> 0 | BB46: =BA46 -> 0 | BC46: =BB46/AY46 -> #DIV/0! | BH46: =BG46 -> 0 | BI46: =BH46/BE46 -> #DIV/0!
A47: 37 | F47: =E47 -> 0 | H47: =G47 -> 0 | J47: =I47 -> 0 | L47: =K47 -> 0 | N47: =M47 -> 0 | P47: =O47 -> 0 | Q47: =O47+M47+K47+I47+G47+E47 -> 0 | R47: =Q47 -> 0 | S47: =R47/C47 -> #DIV/0! | U47: =T47 -> 0 | W47: =V47 -> 0 | Y47: =X47 -> 0 | AB47: 37 | AC47: =AW47 -> 0 | AF47: =AD47+AE47 -> 0 | AH47: =AG47 -> 0 | AI47: =AD47+AE47-AG47 -> 0 | AJ47: =Q47/AG47 -> #DIV/0! | AK47: =R47/AH47 -> #DIV/0! | AW47: =B47 -> 0 | BB47: =BA47 -> 0 | BC47: =BB47/AY47 -> #DIV/0! | BH47: =BG47 -> 0 | BI47: =BH47/BE47 -> #DIV/0!
A48: 38 | F48: =E48 -> 0 | H48: =G48 -> 0 | J48: =I48 -> 0 | L48: =K48 -> 0 | N48: =M48 -> 0 | P48: =O48 -> 0 | Q48: =O48+M48+K48+I48+G48+E48 -> 0 | R48: =Q48 -> 0 | S48: =R48/C48 -> #DIV/0! | U48: =T48 -> 0 | W48: =V48 -> 0 | Y48: =X48 -> 0 | AB48: 38 | AC48: =AW48 -> 0 | AF48: =AD48+AE48 -> 0 | AH48: =AG48 -> 0 | AI48: =AD48+AE48-AG48 -> 0 | AJ48: =Q48/AG48 -> #DIV/0! | AK48: =R48/AH48 -> #DIV/0! | AW48: =B48 -> 0 | BB48: =BA48 -> 0 | BC48: =BB48/AY48 -> #DIV/0! | BH48: =BG48 -> 0 | BI48: =BH48/BE48 -> #DIV/0!
A49: 39 | F49: =E49 -> 0 | H49: =G49 -> 0 | J49: =I49 -> 0 | L49: =K49 -> 0 | N49: =M49 -> 0 | P49: =O49 -> 0 | Q49: =O49+M49+K49+I49+G49+E49 -> 0 | R49: =Q49 -> 0 | S49: =R49/C49 -> #DIV/0! | U49: =T49 -> 0 | W49: =V49 -> 0 | Y49: =X49 -> 0 | AB49: 39 | AC49: =AW49 -> 0 | AF49: =AD49+AE49 -> 0 | AH49: =AG49 -> 0 | AI49: =AD49+AE49-AG49 -> 0 | AJ49: =Q49/AG49 -> #DIV/0! | AK49: =R49/AH49 -> #DIV/0! | AW49: =B49 -> 0 | BB49: =BA49 -> 0 | BC49: =BB49/AY49 -> #DIV/0! | BH49: =BG49 -> 0 | BI49: =BH49/BE49 -> #DIV/0!
A50: 40 | F50: =E50 -> 0 | H50: =G50 -> 0 | J50: =I50 -> 0 | L50: =K50 -> 0 | N50: =M50 -> 0 | P50: =O50 -> 0 | Q50: =O50+M50+K50+I50+G50+E50 -> 0 | R50: =Q50 -> 0 | S50: =R50/C50 -> #DIV/0! | U50: =T50 -> 0 | W50: =V50 -> 0 | Y50: =X50 -> 0 | AB50: 40 | AC50: =AW50 -> 0 | AF50: =AD50+AE50 -> 0 | AH50: =AG50 -> 0 | AI50: =AD50+AE50-AG50 -> 0 | AJ50: =Q50/AG50 -> #DIV/0! | AK50: =R50/AH50 -> #DIV/0! | AW50: =B50 -> 0 | BB50: =BA50 -> 0 | BC50: =BB50/AY50 -> #DIV/0! | BH50: =BG50 -> 0 | BI50: =BH50/BE50 -> #DIV/0!
A51: الاجمالي | C51: =SUM(C11:C50) -> 97446 | D51: =SUM(D11:D50) -> 107 | E51: =SUM(E11:E50) -> 178 | F51: =SUM(F11:F50) -> 178 | G51: =SUM(G11:G50) -> 3195 | H51: =SUM(H11:H50) -> 3195 | I51: =SUM(I11:I50) -> 17232 | J51: =SUM(J11:J50) -> 17232 | ... R51: =SUM(R11:R50) -> 20605 | S51: =R51/C51 -> 0.21145044 | T51: =SUM(T11:T50) -> 2841 | U51: =SUM(U11:U50) -> 2841 | V51: =SUM(V11:V50) -> 34 | W51: =SUM(W11:W50) -> 34 | X51: =SUM(X11:X50) -> 1 | Y51: =SUM(Y11:Y50) -> 1 | AB51: اجمالي الوحدات | AD51: =SUM(AD11:AD50) -> 8550 | AE51: =SUM(AE11:AE50) -> 0 | AF51: =SUM(AF11:AF50) -> 8550 | AG51: =SUM(AG11:AG50) -> 2120 | AH51: =SUM(AH11:AH50) -> 2120 | AI51: =SUM(AI11:AI50) -> 6430 | AJ51: =Q51/AG51 -> 9.7193396 | AK51: =R51/AH51 -> 9.7193396 | AW51: الاجمالي | AX51: =SUM(AX11:AX50) -> 121 | AY51: =SUM(AY11:AY50) -> 50910 | AZ51: =SUM(AZ11:AZ50) -> 50 | BA51: =SUM(BA11:BA50) -> 18396 | BB51: =SUM(BB11:BB50) -> 18396 | BC51: =BB51/AY51 -> 0.36134355 | BD51: =SUM(BD11:BD50) -> 241 | BE51: =SUM(BE11:BE50) -> 14990 | BF51: =SUM(BF11:BF50) -> 23 | BG51: =SUM(BG11:BG50) -> 1354 | BH51: =SUM(BH11:BH50) -> 1354 | BI51: =BH51/BE51 -> 0.090326885
G54: مراقب التطعيمات مسؤل التطعيمات مدير الوقائي مدير الادارة
AB55: مراقب التطعيمات / مسئول التطعيمات / المدير الوقائى / مدير الادارة / | AX55: مراقب التطعيمات / مسئول التطعيمات / المدير الوقائى / مدير الادارة /

Sheet 2
A1: وزارة الصحة والسكان | AB1: وزارة الصحة والسكان | AW1: وزارة الصحة والسكان
A2: قطاع الطب الوقائي والصحة العامة | AB2: قطاع الطب الوقائي والصحة العامة | AW2: قطاع الطب الوقائي والصحة العامة
A3: الإدارة المركزية للصحة العامة | AB3: الإدارة المركزية للصحة العامة | AW3: الإدارة المركزية للصحة العامة
A4: الإدارة العامة لمكافحة الأمراض المعدية | AB4: الإدارة العامة لمكافحة الأمراض المعدية | AW4: الإدارة العامة لمكافحة الأمراض المعدية
A5: البرنامج الموسع للتطعيمات | AB5: البرنامج الموسع للتطعيمات | AW5: البرنامج الموسع للتطعيمات
A6: بيان باعداد المتطعمين و المتغيبين و الاثار الجانبية بالحملة القومية للتطعيم بطعم MR | AF6: البلاغ اليومى لحركة الطعوم بالحملة القومية للتطعيم بطعم MR | AY6: بيان المدارس و الحضانات بالحملة القومية للتطعيم بطعم MR
A7: مديرية الشئون الصحية / المنوفية الإدارة الصحية / قويسنا التاريخ / 26/10/2026 اليوم / الاثنين | AJ7: مديرية الشئون الصحية / الإدارة الصحية / التاريخ/ اليوم / | BC7: مديرية الشئون الصحية / الإدارة الصحية / التاريخ/ اليوم /
A8: م | B8: اسم الوحدة/ مكتب الصحة | C8: المستهدف | D8: عدد الفرق | E8: المتطعمين المصريين | K8: المتطعمين غير المصريين | Q8: الاجمالى | S8: النسبة | T8: المتغيبين عن التطعيم | V8: المطعمين من المتغيبين | X8: الاثار الجانبية | AB8: م | AC8: اسم الوحدة | AD8: الرصيد اول اليوم | AE8: عدد الزجاجات الواردة | AG8: عدد الزجاجات المستهلكة | AI8: عدد الزجاجات المتبقية | AJ8: معدل الزجاجة اليوم | AK8: معدل الزجاجة حتي اليوم | AM8: مخزن طعوم الادارة | AN8: التشغيلة | AO8: الرصيد اول اليوم | AP8: عدد الزجاجات الواردة | AR8: عدد الزجاجات المنصرفة | AT8: عدد الزجاجات المتبقية | AW8: اسم الوحدة | AX8: بيان المدارس | BD8: بيان الحضانات
E9: من 9 شهور لأقل من عام | G9: من عام لأقل من5 سنوات | I9: من 5 سنوات الى 10 سنة | K9: من 9 شهور لأقل من عام | M9: من عام لأقل من5 سنوات | O9: من 5 سنوات الى 10 سنة | AP9: اليوم | AQ9: حتى اليوم | AR9: اليوم | AS9: حتى اليوم | AX9: عدد المدارس | AY9: المستهدف | AZ9: عدد المدارس التي تم زيارتها حتى اليوم | BA9: عدد المتطعمين اليوم | BB9: عدد المتطعمين حتى اليوم | BC9: النسبة | BD9: عدد الحضانات | BE9: المستهدف | BF9: عدد الحضانات التي تم زيارتها حتى اليوم | BG9: عدد المتطعمين اليوم | BH9: عدد المتطعمين حتى اليوم | BI9: النسبة
E10: اليوم | F10: حتى اليوم | G10: اليوم | H10: حتى اليوم | I10: اليوم | J10: حتى اليوم | K10: اليوم | L10: حتى اليوم | M10: اليوم | N10: حتى اليوم | O10: اليوم | P10: حتى اليوم | Q10: اليوم | R10: حتى اليوم | T10: اليوم | U10: حتى اليوم | V10: اليوم | W10: حتى اليوم | X10: اليوم | Y10: حتى اليوم | AE10: اليوم | AF10: حتى اليوم | AG10: اليوم | AH10: حتى اليوم | AN10: ='1'!AN10 -> 0124W120 | AO10: ='1'!AT10 -> 73 | AP10: 0 | AQ10: =AP10+'1'!AQ10 -> 73 | AS10: =AR10+'1'!AS10 -> 0 | AT10: =AO10+AP10-AR10 -> 73
A11: 1 | B11: ='1'!B11 -> مكتب الصحة | C11: ='1'!C11 -> 12251 | D11: 13 | E11: 12 | F11: =E11+'1'!F11 -> 23 | G11: 657 | H11: =G11+'1'!H11 -> 1074 | I11: 1722 | J11: =I11+'1'!J11 -> 3735 | K11: 0 | L11: =K11+'1'!L11 -> 0 | M11: 0 | N11: =M11+'1'!N11 -> 0 | O11: 0 | P11: =O11+'1'!P11 -> 0 | Q11: =O11+M11+K11+I11+G11+E11 -> 2391 | R11: =Q11+'1'!R11 -> 4832 | S11: =R11/C11 -> 0.39441678 | T11: 532 | U11: =T11+'1'!U11 -> 934 | V11: 0 | W11: =V11+'1'!W11 -> 0 | X11: 0 | Y11: =X11+'1'!Y11 -> 0 | AB11: 1 | AC11: =AW11 -> مكتب الصحة | AD11: ='1'!AI11 -> 827 | AE11: 0 | AF11: =AE11+'1'!AF11 -> 1076 | AG11: 243 | AH11: =AG11+'1'!AH11 -> 492 | AI11: =AD11+AE11-AG11 -> 584 | AJ11: =Q11/AG11 -> 9.8395062 | AK11: =R11/AH11 -> 9.8211382 | AN11: ='1'!AN11 -> 420604325A | AO11: ='1'!AT11 -> 6430 | AQ11: =AP11+'1'!AQ11 -> 8550 | AR11: 1931 | AS11: =AR11+'1'!AS11 -> 4051 | AT11: =AO11+AP11-AR11 -> 4499 | AW11: =B11 -> مكتب الصحة | AX11: ='1'!AX11 -> 11 | AY11: ='1'!AY11 -> 8411 | AZ11: 8 | BA11: 1925 | BB11: =BA11+'1'!BB11 -> 4176 | BC11: =BB11/AY11 -> 0.49649269 | BD11: ='1'!BD11 -> 27 | BE11: ='1'!BE11 -> 1746 | BF11: 4 | BG11: 131 | BH11: =BG11+'1'!BH11 -> 131 | BI11: =BH11/BE11 -> 0.075028637
A12: 2 | B12: ='1'!B12 -> شبرابخـــــــــــوم | C12: ='1'!C12 -> 4445 | D12: 4 | E12: 3 | F12: =E12+'1'!F12 -> 4 | G12: 102 | H12: =G12+'1'!H12 -> 127 | I12: 668 | J12: =I12+'1'!J12 -> 1320 | K12: 0 | L12: =K12+'1'!L12 -> 0 | M12: 0 | N12: =M12+'1'!N12 -> 0 | O12: 0 | P12: =O12+'1'!P12 -> 0 | Q12: =O12+M12+K12+I12+G12+E12 -> 773 | R12: =Q12+'1'!R12 -> 1451 | S12: =R12/C12 -> 0.3264342 | T12: 140 | U12: =T12+'1'!U12 -> 242 | V12: 3 | W12: =V12+'1'!W12 -> 4 | X12: 0 | Y12: =X12+'1'!Y12 -> 0 | AB12: 2 | AC12: =AW12 -> شبرابخـــــــــــوم | AD12: ='1'!AI12 -> 320 | AE12: 0 | AF12: =AE12+'1'!AF12 -> 390 | AG12: 78 | AH12: =AG12+'1'!AH12 -> 148 | AI12: =AD12+AE12-AG12 -> 242 | AJ12: =Q12/AG12 -> 9.9102564 | AK12: =R12/AH12 -> 9.8040541 | AN12: 420604225A | AO12: ='1'!AT12 -> 0 | AP12: 100 | AQ12: =AP12+'1'!AQ12 -> 100 | AS12: =AR12+'1'!AS12 -> 0 | AT12: =AO12+AP12-AR12 -> 100 | AW12: =B12 -> شبرابخـــــــــــوم | AX12: ='1'!AX12 -> 6 | AY12: ='1'!AY12 -> 2215 | AZ12: 2 | BA12: 773 | BB12: =BA12+'1'!BB12 -> 1451 | BC12: =BB12/AY12 -> 0.65507901 | BD12: ='1'!BD12 -> 16 | BE12: ='1'!BE12 -> 729 | BF12: 0 | BG12: 0 | BH12: =BG12+'1'!BH12 -> 0 | BI12: =BH12/BE12 -> 0
A13: 3 | B13: ='1'!B13 -> ميت بره | C13: ='1'!C13 -> 11614 | D13: 8 | E13: 5 | F13: =E13+'1'!F13 -> 18 | G13: 114 | H13: =G13+'1'!H13 -> 159 | I13: 1426 | J13: =I13+'1'!J13 -> 2971 | K13: 0 | L13: =K13+'1'!L13 -> 0 | M13: 0 | N13: =M13+'1'!N13 -> 0 | O13: 0 | P13: =O13+'1'!P13 -> 0 | Q13: =O13+M13+K13+I13+G13+E13 -> 1545 | R13: =Q13+'1'!R13 -> 3148 | S13: =R13/C13 -> 0.27105218 | T13: 221 | U13: =T13+'1'!U13 -> 420 | V13: 0 | W13: =V13+'1'!W13 -> 0 | X13: 0 | Y13: =X13+'1'!Y13 -> 0 | AB13: 3 | AC13: =AW13 -> ميت بره | AD13: ='1'!AI13 -> 857 | AE13: 0 | AF13: =AE13+'1'!AF13 -> 1020 | AG13: 156 | AH13: =AG13+'1'!AH13 -> 319 | AI13: =AD13+AE13-AG13 -> 701 | AJ13: =Q13/AG13 -> 9.9038462 | AK13: =R13/AH13 -> 9.8683386 | AN13: اجمالي المخزن | AO13: =SUM(AO10:AO12) -> 6503 | AP13: =SUM(AP10:AP12) -> 100 | AQ13: =SUM(AQ10:AQ12) -> 8723 | AR13: =SUM(AR10:AR12) -> 1931 | AS13: =SUM(AS10:AS12) -> 4051 | AT13: =SUM(AT10:AT12) -> 4672 | AW13: =B13 -> ميت بره | AX13: ='1'!AX13 -> 8 | AY13: ='1'!AY13 -> 4849 | AZ13: 3 | BA13: 1395 | BB13: =BA13+'1'!BB13 -> 2928 | BC13: =BB13/AY13 -> 0.60383584 | BD13: ='1'!BD13 -> 21 | BE13: ='1'!BE13 -> 1129 | BF13: 0 | BG13: 0 | BH13: =BG13+'1'!BH13 -> 0 | BI13: =BH13/BE13 -> 0
A14: 4 | B14: ='1'!B14 -> أبنــــــــــــــــهس | C14: ='1'!C14 -> 5029 | D14: 4 | E14: 2 | F14: =E14+'1'!F14 -> 6 | G14: 10 | H14: =G14+'1'!H14 -> 39 | I14: 771 | J14: =I14+'1'!J14 -> 1657 | K14: 0 | L14: =K14+'1'!L14 -> 0 | M14: 0 | N14: =M14+'1'!N14 -> 0 | O14: 0 | P14: =O14+'1'!P14 -> 0 | Q14: =O14+M14+K14+I14+G14+E14 -> 783 | R14: =Q14+'1'!R14 -> 1702 | S14: =R14/C14 -> 0.33843707 | T14: 111 | U14: =T14+'1'!U14 -> 188 | V14: 19 | W14: =V14+'1'!W14 -> 19 | X14: 0 | Y14: =X14+'1'!Y14 -> 0 | AB14: 4 | AC14: =AW14 -> أبنــــــــــــــــهس | AD14: ='1'!AI14 -> 346 | AE14: 0 | AF14: =AE14+'1'!AF14 -> 440 | AG14: 80 | AH14: =AG14+'1'!AH14 -> 174 | AI14: =AD14+AE14-AG14 -> 266 | AJ14: =Q14/AG14 -> 9.7875 | AK14: =R14/AH14 -> 9.7816092 | AM14: احمالي الوحدات ومخزن الادارة | AT14: =AT13+AI51 -> 9181 | AW14: =B14 -> أبنــــــــــــــــهس | AX14: ='1'!AX14 -> 7 | AY14: ='1'!AY14 -> 2531 | AZ14: 5 | BA14: 783 | BB14: =BA14+'1'!BB14 -> 1702 | BC14: =BB14/AY14 -> 0.67246148 | BD14: ='1'!BD14 -> 23 | BE14: ='1'!BE14 -> 921 | BF14: 0 | BG14: 0 | BH14: =BG14+'1'!BH14 -> 0 | BI14: =BH14/BE14 -> 0
A15: 5 | B15: ='1'!B15 -> ميت ســـــــــراج | C15: ='1'!C15 -> 2369 | D15: 3 | E15: 2 | F15: =E15+'1'!F15 -> 3 | G15: 26 | H15: =G15+'1'!H15 -> 208 | I15: 551 | J15: =I15+'1'!J15 -> 816 | K15: 0 | L15: =K15+'1'!L15 -> 0 | M15: 0 | N15: =M15+'1'!N15 -> 0 | O15: 0 | P15: =O15+'1'!P15 -> 0 | Q15: =O15+M15+K15+I15+G15+E15 -> 579 | R15: =Q15+'1'!R15 -> 1027 | S15: =R15/C15 -> 0.43351625 | T15: 44 | U15: =T15+'1'!U15 -> 93 | V15: 18 | W15: =V15+'1'!W15 -> 18 | X15: 0 | Y15: =X15+'1'!Y15 -> 0 | AB15: 5 | AC15: =AW15 -> ميت ســـــــــراج | AD15: ='1'!AI15 -> 163 | AE15: 0 | AF15: =AE15+'1'!AF15 -> 209 | AG15: 59 | AH15: =AG15+'1'!AH15 -> 105 | AI15: =AD15+AE15-AG15 -> 104 | AJ15: =Q15/AG15 -> 9.8135593 | AK15: =R15/AH15 -> 9.7809524 | AW15: =B15 -> ميت ســـــــــراج | AX15: ='1'!AX15 -> 2 | AY15: ='1'!AY15 -> 1041 | AZ15: 2 | BA15: 549 | BB15: =BA15+'1'!BB15 -> 856 | BC15: =BB15/AY15 -> 0.82228626 | BD15: ='1'!BD15 -> 5 | BE15: ='1'!BE15 -> 310 | BF15: 0 | BG15: 0 | BH15: =BG15+'1'!BH15 -> 141 | BI15: =BH15/BE15 -> 0.45483871
A16: 6 | B16: ='1'!B16 -> أم خــــــــــــــنان | C16: ='1'!C16 -> 4900 | D16: 4 | E16: 5 | F16: =E16+'1'!F16 -> 8 | G16: 92 | H16: =G16+'1'!H16 -> 213 | I16: 649 | J16: =I16+'1'!J16 -> 1318 | K16: 0 | L16: =K16+'1'!L16 -> 0 | M16: 0 | N16: =M16+'1'!N16 -> 0 | O16: 0 | P16: =O16+'1'!P16 -> 0 | Q16: =O16+M16+K16+I16+G16+E16 -> 746 | R16: =Q16+'1'!R16 -> 1539 | S16: =R16/C16 -> 0.31408163 | T16: 144 | U16: =T16+'1'!U16 -> 258 | V16: 0 | W16: =V16+'1'!W16 -> 0 | X16: 0 | Y16: =X16+'1'!Y16 -> 0 | AB16: 6 | AC16: =AW16 -> أم خــــــــــــــنان | AD16: ='1'!AI16 -> 350 | AE16: 0 | AF16: =AE16+'1'!AF16 -> 430 | AG16: 76 | AH16: =AG16+'1'!AH16 -> 156 | AI16: =AD16+AE16-AG16 -> 274 | AJ16: =Q16/AG16 -> 9.8157895 | AK16: =R16/AH16 -> 9.8653846 | AW16: =B16 -> أم خــــــــــــــنان | AX16: ='1'!AX16 -> 8 | AY16: ='1'!AY16 -> 2981 | AZ16: 2 | BA16: 704 | BB16: =BA16+'1'!BB16 -> 1468 | BC16: =BB16/AY16 -> 0.4924522 | BD16: ='1'!BD16 -> 12 | BE16: ='1'!BE16 -> 1313 | BF16: 0 | BG16: 0 | BH16: =BG16+'1'!BH16 -> 0 | BI16: =BH16/BE16 -> 0
A17: 7 | B17: ='1'!B17 -> أجهور الرمل | C17: ='1'!C17 -> 3590 | D17: 3 | E17: 8 | F17: =E17+'1'!F17 -> 9 | G17: 304 | H17: =G17+'1'!H17 -> 514 | I17: 372 | J17: =I17+'1'!J17 -> 1001 | K17: 0 | L17: =K17+'1'!L17 -> 0 | M17: 0 | N17: =M17+'1'!N17 -> 0 | O17: 0 | P17: =O17+'1'!P17 -> 0 | Q17: =O17+M17+K17+I17+G17+E17 -> 684 | R17: =Q17+'1'!R17 -> 1524 | S17: =R17/C17 -> 0.42451253 | T17: 199 | U17: =T17+'1'!U17 -> 360 | V17: 51 | W17: =V17+'1'!W17 -> 51 | X17: 0 | Y17: =X17+'1'!Y17 -> 0 | AB17: 7 | AC17: =AW17 -> أجهور الرمل | AD17: ='1'!AI17 -> 230 | AE17: 0 | AF17: =AE17+'1'!AF17 -> 316 | AG17: 70 | AH17: =AG17+'1'!AH17 -> 156 | AI17: =AD17+AE17-AG17 -> 160 | AJ17: =Q17/AG17 -> 9.7714286 | AK17: =R17/AH17 -> 9.7692308 | AW17: =B17 -> أجهور الرمل | AX17: ='1'!AX17 -> 4 | AY17: ='1'!AY17 -> 1796 | AZ17: 1 | BA17: 365 | BB17: =BA17+'1'!BB17 -> 963 | BC17: =BB17/AY17 -> 0.53619154 | BD17: ='1'!BD17 -> 3 | BE17: ='1'!BE17 -> 100 | BF17: 3 | BG17: 199 | BH17: =BG17+'1'!BH17 -> 441 | BI17: =BH17/BE17 -> 4.41
A18: 8 | B18: ='1'!B18 -> منشأة دمــــــــــلو | C18: ='1'!C18 -> 1320 | D18: 2 | E18: 2 | F18: =E18+'1'!F18 -> 13 | G18: 243 | H18: =G18+'1'!H18 -> 341 | I18: 180 | J18: =I18+'1'!J18 -> 682 | K18: 0 | L18: =K18+'1'!L18 -> 0 | M18: 0 | N18: =M18+'1'!N18 -> 0 | O18: 0 | P18: =O18+'1'!P18 -> 0 | Q18: =O18+M18+K18+I18+G18+E18 -> 425 | R18: =Q18+'1'!R18 -> 1036 | S18: =R18/C18 -> 0.78484848 | T18: 60 | U18: =T18+'1'!U18 -> 151 | V18: 7 | W18: =V18+'1'!W18 -> 15 | X18: 0 | Y18: =X18+'1'!Y18 -> 0 | AB18: 8 | AC18: =AW18 -> منشأة دمــــــــــلو | AD18: ='1'!AI18 -> 52 | AE18: 0 | AF18: =AE18+'1'!AF18 -> 115 | AG18: 46 | AH18: =AG18+'1'!AH18 -> 109 | AI18: =AD18+AE18-AG18 -> 6 | AJ18: =Q18/AG18 -> 9.2391304 | AK18: =R18/AH18 -> 9.5045872 | AW18: =B18 -> منشأة دمــــــــــلو | AX18: ='1'!AX18 -> 2 | AY18: ='1'!AY18 -> 896 | AZ18: 2 | BA18: 187 | BB18: =BA18+'1'!BB18 -> 748 | BC18: =BB18/AY18 -> 0.83482143 | BD18: ='1'!BD18 -> 8 | BE18: ='1'!BE18 -> 340 | BF18: 3 | BG18: 188 | BH18: =BG18+'1'!BH18 -> 188 | BI18: =BH18/BE18 -> 0.55294118
A19: 9 | B19: ='1'!B19 -> شـــــــــــــرانيس | C19: ='1'!C19 -> 1414 | D19: 2 | E19: 4 | F19: =E19+'1'!F19 -> 11 | G19: 98 | H19: =G19+'1'!H19 -> 112 | I19: 133 | J19: =I19+'1'!J19 -> 557 | K19: 0 | L19: =K19+'1'!L19 -> 0 | M19: 0 | N19: =M19+'1'!N19 -> 0 | O19: 0 | P19: =O19+'1'!P19 -> 0 | Q19: =O19+M19+K19+I19+G19+E19 -> 235 | R19: =Q19+'1'!R19 -> 680 | S19: =R19/C19 -> 0.48090523 | T19: 55 | U19: =T19+'1'!U19 -> 101 | V19: 0 | W19: =V19+'1'!W19 -> 0 | X19: 0 | Y19: =X19+'1'!Y19 -> 0 | AB19: 9 | AC19: =AW19 -> شـــــــــــــرانيس | AD19: ='1'!AI19 -> 79 | AE19: 0 | AF19: =AE19+'1'!AF19 -> 125 | AG19: 25 | AH19: =AG19+'1'!AH19 -> 71 | AI19: =AD19+AE19-AG19 -> 54 | AJ19: =Q19/AG19 -> 9.4 | AK19: =R19/AH19 -> 9.5774648 | AW19: =B19 -> شـــــــــــــرانيس | AX19: ='1'!AX19 -> 2 | AY19: ='1'!AY19 -> 675 | AZ19: 1 | BA19: 142 | BB19: =BA19+'1'!BB19 -> 569 | BC19: =BB19/AY19 -> 0.84296296 | BD19: ='1'!BD19 -> 2 | BE19: ='1'!BE19 -> 397 | BF19: 1 | BG19: 63 | BH19: =BG19+'1'!BH19 -> 63 | BI19: =BH19/BE19 -> 0.15869018
A20: 10 | B20: ='1'!B20 -> قويســـــــــنا البلد | C20: ='1'!C20 -> 4115 | D20: 3 | E20: 7 | F20: =E20+'1'!F20 -> 21 | G20: 143 | H20: =G20+'1'!H20 -> 175 | I20: 520 | J20: =I20+'1'!J20 -> 1047 | K20: 0 | L20: =K20+'1'!L20 -> 0 | M20: 0 | N20: =M20+'1'!N20 -> 0 | O20: 0 | P20: =O20+'1'!P20 -> 0 | Q20: =O20+M20+K20+I20+G20+E20 -> 670 | R20: =Q20+'1'!R20 -> 1243 | S20: =R20/C20 -> 0.30206561 | T20: 165 | U20: =T20+'1'!U20 -> 319 | V20: 71 | W20: =V20+'1'!W20 -> 71 | X20: 0 | Y20: =X20+'1'!Y20 -> 0 | AB20: 10 | AC20: =AW20 -> قويســـــــــنا البلد | AD20: ='1'!AI20 -> 302 | AE20: 0 | AF20: =AE20+'1'!AF20 -> 360 | AG20: 67 | AH20: =AG20+'1'!AH20 -> 125 | AI20: =AD20+AE20-AG20 -> 235 | AJ20: =Q20/AG20 -> 10 | AK20: =R20/AH20 -> 9.944 | AW20: =B20 -> قويســـــــــنا البلد | AX20: ='1'!AX20 -> 2 | AY20: ='1'!AY20 -> 1539 | AZ20: 1 | BA20: 610 | BB20: =BA20+'1'!BB20 -> 1133 | BC20: =BB20/AY20 -> 0.73619233 | BD20: ='1'!BD20 -> 7 | BE20: ='1'!BE20 -> 580 | BF20: 0 | BG20: 0 | BH20: =BG20+'1'!BH20 -> 0 | BI20: =BH20/BE20 -> 0
A21: 11 | B21: ='1'!B21 -> بجيرم | C21: ='1'!C21 -> 1782 | D21: 3 | E21: 3 | F21: =E21+'1'!F21 -> 8 | G21: 209 | H21: =G21+'1'!H21 -> 310 | I21: 281 | J21: =I21+'1'!J21 -> 686 | K21: 0 | L21: =K21+'1'!L21 -> 0 | M21: 0 | N21: =M21+'1'!N21 -> 0 | O21: 0 | P21: =O21+'1'!P21 -> 0 | Q21: =O21+M21+K21+I21+G21+E21 -> 493 | R21: =Q21+'1'!R21 -> 1004 | S21: =R21/C21 -> 0.5634119 | T21: 70 | U21: =T21+'1'!U21 -> 126 | V21: 19 | W21: =V21+'1'!W21 -> 19 | X21: 0 | Y21: =X21+'1'!Y21 -> 0 | AB21: 11 | AC21: =AW21 -> بجيرم | AD21: ='1'!AI21 -> 105 | AE21: 0 | AF21: =AE21+'1'!AF21 -> 157 | AG21: 51 | AH21: =AG21+'1'!AH21 -> 103 | AI21: =AD21+AE21-AG21 -> 54 | AJ21: =Q21/AG21 -> 9.6666667 | AK21: =R21/AH21 -> 9.7475728 | AW21: =B21 -> بجيرم | AX21: ='1'!AX21 -> 4 | AY21: ='1'!AY21 -> 946 | AZ21: 4 | BA21: 174 | BB21: =BA21+'1'!BB21 -> 634 | BC21: =BB21/AY21 -> 0.67019027 | BD21: ='1'!BD21 -> 4 | BE21: ='1'!BE21 -> 99 | BF21: 2 | BG21: 69 | BH21: =BG21+'1'!BH21 -> 69 | BI21: =BH21/BE21 -> 0.6969697
A22: 12 | B22: ='1'!B22 -> كفر بنى غريـــان | C22: ='1'!C22 -> 2184 | D22: 3 | E22: 6 | F22: =E22+'1'!F22 -> 9 | G22: 120 | H22: =G22+'1'!H22 -> 301 | I22: 377 | J22: =I22+'1'!J22 -> 819 | L22: =K22+'1'!L22 -> 0 | N22: =M22+'1'!N22 -> 0 | P22: =O22+'1'!P22 -> 0 | Q22: =O22+M22+K22+I22+G22+E22 -> 503 | R22: =Q22+'1'!R22 -> 1129 | S22: =R22/C22 -> 0.51694139 | T22: 40 | U22: =T22+'1'!U22 -> 108 | V22: 0 | W22: =V22+'1'!W22 -> 0 | X22: 0 | Y22: =X22+'1'!Y22 -> 0 | AB22: 12 | AC22: =AW22 -> كفر بنى غريـــان | AD22: ='1'!AI22 -> 129 | AE22: 0 | AF22: =AE22+'1'!AF22 -> 192 | AG22: 54 | AH22: =AG22+'1'!AH22 -> 117 | AI22: =AD22+AE22-AG22 -> 75 | AJ22: =Q22/AG22 -> 9.3148148 | AK22: =R22/AH22 -> 9.6495726 | AW22: =B22 -> كفر بنى غريـــان | AX22: ='1'!AX22 -> 3 | AY22: ='1'!AY22 -> 1327 | AZ22: 2 | BA22: 363 | BB22: =BA22+'1'!BB22 -> 929 | BC22: =BB22/AY22 -> 0.70007536 | BD22: ='1'!BD22 -> 9 | BE22: ='1'!BE22 -> 381 | BF22: 2 | BG22: 95 | BH22: =BG22+'1'!BH22 -> 229 | BI22: =BH22/BE22 -> 0.60104987
A23: 13 | B23: ='1'!B23 -> بــقســـــــــــــــــا | C23: ='1'!C23 -> 862 | D23: 2 | E23: 3 | F23: =E23+'1'!F23 -> 7 | G23: 78 | H23: =G23+'1'!H23 -> 116 | I23: 18 | J23: =I23+'1'!J23 -> 344 | K23: 0 | L23: =K23+'1'!L23 -> 0 | M23: 0 | N23: =M23+'1'!N23 -> 0 | O23: 0 | P23: =O23+'1'!P23 -> 0 | Q23: =O23+M23+K23+I23+G23+E23 -> 99 | R23: =Q23+'1'!R23 -> 467 | S23: =R23/C23 -> 0.54176334 | T23: 9 | U23: =T23+'1'!U23 -> 36 | V23: 9 | W23: =V23+'1'!W23 -> 14 | X23: 0 | Y23: =X23+'1'!Y23 -> 0 | AB23: 13 | AC23: =AW23 -> بــقســـــــــــــــــا | AD23: ='1'!AI23 -> 38 | AE23: 0 | AF23: =AE23+'1'!AF23 -> 75 | AG23: 10 | AH23: =AG23+'1'!AH23 -> 47 | AI23: =AD23+AE23-AG23 -> 28 | AJ23: =Q23/AG23 -> 9.9 | AK23: =R23/AH23 -> 9.9361702 | AW23: =B23 -> بــقســـــــــــــــــا | AX23: ='1'!AX23 -> 1 | AY23: ='1'!AY23 -> 311 | AZ23: 1 | BA23: 9 | BB23: =BA23+'1'!BB23 -> 297 | BC23: =BB23/AY23 -> 0.95498392 | BD23: ='1'!BD23 -> 1 | BE23: ='1'!BE23 -> 40 | BF23: 1 | BG23: 30 | BH23: =BG23+'1'!BH23 -> 30 | BI23: =BH23/BE23 -> 0.75
A24: 14 | B24: ='1'!B24 -> كفــــــــر الأكرم | C24: ='1'!C24 -> 918 | D24: 2 | E24: 2 | F24: =E24+'1'!F24 -> 2 | G24: 57 | H24: =G24+'1'!H24 -> 119 | I24: 195 | J24: =I24+'1'!J24 -> 380 | K24: 0 | L24: =K24+'1'!L24 -> 0 | M24: 0 | N24: =M24+'1'!N24 -> 0 | O24: 0 | P24: =O24+'1'!P24 -> 0 | Q24: =O24+M24+K24+I24+G24+E24 -> 254 | R24: =Q24+'1'!R24 -> 501 | S24: =R24/C24 -> 0.54575163 | T24: 30 | U24: =T24+'1'!U24 -> 66 | V24: 7 | W24: =V24+'1'!W24 -> 7 | X24: 0 | Y24: =X24+'1'!Y24 -> 0 | AB24: 14 | AC24: =AW24 -> كفــــــــر الأكرم | AD24: ='1'!AI24 -> 55 | AE24: 0 | AF24: =AE24+'1'!AF24 -> 80 | AG24: 26 | AH24: =AG24+'1'!AH24 -> 51 | AI24: =AD24+AE24-AG24 -> 29 | AJ24: =Q24/AG24 -> 9.7692308 | AK24: =R24/AH24 -> 9.8235294 | AW24: =B24 -> كفــــــــر الأكرم | AX24: ='1'!AX24 -> 2 | AY24: ='1'!AY24 -> 540 | AZ24: 2 | BA24: 193 | BB24: =BA24+'1'!BB24 -> 378 | BC24: =BB24/AY24 -> 0.7 | BD24: ='1'!BD24 -> 2 | BE24: ='1'!BE24 -> 115 | BF24: 2 | BG24: 31 | BH24: =BG24+'1'!BH24 -> 63 | BI24: =BH24/BE24 -> 0.54782609
A25: 15 | B25: ='1'!B25 -> كفـــــــــر إبنهس | C25: ='1'!C25 -> 2072 | D25: 3 | E25: 5 | F25: =E25+'1'!F25 -> 5 | G25: 148 | H25: =G25+'1'!H25 -> 152 | I25: 240 | J25: =I25+'1'!J25 -> 845 | K25: 0 | L25: =K25+'1'!L25 -> 0 | M25: 0 | N25: =M25+'1'!N25 -> 0 | O25: 0 | P25: =O25+'1'!P25 -> 0 | Q25: =O25+M25+K25+I25+G25+E25 -> 393 | R25: =Q25+'1'!R25 -> 1002 | S25: =R25/C25 -> 0.48359073 | T25: 60 | U25: =T25+'1'!U25 -> 168 | V25: 42 | W25: =V25+'1'!W25 -> 42 | X25: 0 | Y25: =X25+'1'!Y25 -> 0 | AB25: 15 | AC25: =AW25 -> كفـــــــــر إبنهس | AD25: ='1'!AI25 -> 104 | AE25: 0 | AF25: =AE25+'1'!AF25 -> 180 | AG25: 40 | AH25: =AG25+'1'!AH25 -> 116 | AI25: =AD25+AE25-AG25 -> 64 | AJ25: =Q25/AG25 -> 9.825 | AK25: =R25/AH25 -> 8.637931 | AW25: =B25 -> كفـــــــــر إبنهس | AX25: ='1'!AX25 -> 3 | AY25: ='1'!AY25 -> 1013 | AZ25: 3 | BA25: 228 | BB25: =BA25+'1'!BB25 -> 830 | BC25: =BB25/AY25 -> 0.81934847 | BD25: ='1'!BD25 -> 4 | BE25: ='1'!BE25 -> 620 | BF25: 1 | BG25: 107 | BH25: =BG25+'1'!BH25 -> 107 | BI25: =BH25/BE25 -> 0.17258065
A26: 16 | B26: ='1'!B26 -> الرمــــــــــــــالى | C26: ='1'!C26 -> 2699 | D26: 3 | E26: 10 | F26: =E26+'1'!F26 -> 15 | G26: 94 | H26: =G26+'1'!H26 -> 227 | I26: 389 | J26: =I26+'1'!J26 -> 730 | K26: 0 | L26: =K26+'1'!L26 -> 0 | M26: 0 | N26: =M26+'1'!N26 -> 0 | O26: 0 | P26: =O26+'1'!P26 -> 0 | Q26: =O26+M26+K26+I26+G26+E26 -> 493 | R26: =Q26+'1'!R26 -> 972 | S26: =R26/C26 -> 0.36013338 | T26: 59 | U26: =T26+'1'!U26 -> 95 | V26: 42 | W26: =V26+'1'!W26 -> 42 | X26: 0 | Y26: =X26+'1'!Y26 -> 1 | AB26: 16 | AC26: =AW26 -> الرمــــــــــــــالى | AD26: ='1'!AI26 -> 186 | AE26: 0 | AF26: =AE26+'1'!AF26 -> 235 | AG26: 54 | AH26: =AG26+'1'!AH26 -> 103 | AI26: =AD26+AE26-AG26 -> 132 | AJ26: =Q26/AG26 -> 9.1296296 | AK26: =R26/AH26 -> 9.4368932 | AW26: =B26 -> الرمــــــــــــــالى | AX26: ='1'!AX26 -> 3 | AY26: ='1'!AY26 -> 1486 | AZ26: 1 | BA26: 474 | BB26: =BA26+'1'!BB26 -> 899 | BC26: =BB26/AY26 -> 0.60497981 | BD26: ='1'!BD26 -> 3 | BE26: ='1'!BE26 -> 98 | BF26: 0 | BG26: 0 | BH26: =BG26+'1'!BH26 -> 0 | BI26: =BH26/BE26 -> 0
A27: 17 | B27: ='1'!B27 -> مصطــــــــــــاى | C27: ='1'!C27 -> 2666 | D27: 3 | E27: 6 | F27: =E27+'1'!F27 -> 42 | G27: 91 | H27: =G27+'1'!H27 -> 183 | I27: 413 | J27: =I27+'1'!J27 -> 925 | K27: 0 | L27: =K27+'1'!L27 -> 0 | M27: 0 | N27: =M27+'1'!N27 -> 0 | O27: 0 | P27: =O27+'1'!P27 -> 0 | Q27: =O27+M27+K27+I27+G27+E27 -> 510 | R27: =Q27+'1'!R27 -> 1150 | S27: =R27/C27 -> 0.43135784 | T27: 0 | U27: =T27+'1'!U27 -> 45 | V27: 15 | W27: =V27+'1'!W27 -> 15 | X27: 0 | Y27: =X27+'1'!Y27 -> 0 | AB27: 17 | AC27: =AW27 -> مصطــــــــــــاى | AD27: ='1'!AI27 -> 168 | AE27: 0 | AF27: =AE27+'1'!AF27 -> 234 | AG27: 51 | AH27: =AG27+'1'!AH27 -> 117 | AI27: =AD27+AE27-AG27 -> 117 | AJ27: =Q27/AG27 -> 10 | AK27: =R27/AH27 -> 9.8290598 | AW27: =B27 -> مصطــــــــــــاى | AX27: ='1'!AX27 -> 3 | AY27: ='1'!AY27 -> 1709 | AZ27: 2 | BA27: 450 | BB27: =BA27+'1'!BB27 -> 1030 | BC27: =BB27/AY27 -> 0.60269163 | BD27: ='1'!BD27 -> 6 | BE27: ='1'!BE27 -> 696 | BF27: 0 | BG27: 0 | BH27: =BG27+'1'!BH27 -> 0 | BI27: =BH27/BE27 -> 0
A28: 18 | B28: ='1'!B28 -> كفر طـــــــه شبرا | C28: ='1'!C28 -> 1795 | D28: 3 | E28: 4 | F28: =E28+'1'!F28 -> 6 | G28: 36 | H28: =G28+'1'!H28 -> 78 | I28: 373 | J28: =I28+'1'!J28 -> 883 | K28: 0 | L28: =K28+'1'!L28 -> 0 | M28: 0 | N28: =M28+'1'!N28 -> 0 | O28: 0 | P28: =O28+'1'!P28 -> 0 | Q28: =O28+M28+K28+I28+G28+E28 -> 413 | R28: =Q28+'1'!R28 -> 967 | S28: =R28/C28 -> 0.53871866 | T28: 44 | U28: =T28+'1'!U28 -> 97 | V28: 27 | W28: =V28+'1'!W28 -> 27 | X28: 0 | Y28: =X28+'1'!Y28 -> 0 | AB28: 18 | AC28: =AW28 -> كفر طـــــــه شبرا | AD28: ='1'!AI28 -> 99 | AE28: 0 | AF28: =AE28+'1'!AF28 -> 158 | AG28: 42 | AH28: =AG28+'1'!AH28 -> 101 | AI28: =AD28+AE28-AG28 -> 57 | AJ28: =Q28/AG28 -> 9.8333333 | AK28: =R28/AH28 -> 9.5742574 | AW28: =B28 -> كفر طـــــــه شبرا | AX28: ='1'!AX28 -> 4 | AY28: ='1'!AY28 -> 948 | AZ28: 2 | BA28: 315 | BB28: =BA28+'1'!BB28 -> 823 | BC28: =BB28/AY28 -> 0.86814346 | BD28: ='1'!BD28 -> 7 | BE28: ='1'!BE28 -> 300 | BF28: 4 | BG28: 95 | BH28: =BG28+'1'!BH28 -> 132 | BI28: =BH28/BE28 -> 0.44
A29: 19 | B29: ='1'!B29 -> كفر أبـــو الحسن | C29: ='1'!C29 -> 1397 | D29: 2 | E29: 2 | F29: =E29+'1'!F29 -> 2 | G29: 23 | H29: =G29+'1'!H29 -> 46 | I29: 392 | J29: =I29+'1'!J29 -> 749 | K29: 0 | L29: =K29+'1'!L29 -> 0 | M29: 0 | N29: =M29+'1'!N29 -> 0 | O29: 0 | P29: =O29+'1'!P29 -> 0 | Q29: =O29+M29+K29+I29+G29+E29 -> 417 | R29: =Q29+'1'!R29 -> 797 | S29: =R29/C29 -> 0.57050823 | T29: 134 | U29: =T29+'1'!U29 -> 183 | V29: 4 | W29: =V29+'1'!W29 -> 5 | X29: 0 | Y29: =X29+'1'!Y29 -> 0 | AB29: 19 | AC29: =AW29 -> كفر أبـــو الحسن | AD29: ='1'!AI29 -> 84 | AE29: 0 | AF29: =AE29+'1'!AF29 -> 123 | AG29: 43 | AH29: =AG29+'1'!AH29 -> 82 | AI29: =AD29+AE29-AG29 -> 41 | AJ29: =Q29/AG29 -> 9.6976744 | AK29: =R29/AH29 -> 9.7195122 | AW29: =B29 -> كفر أبـــو الحسن | AX29: ='1'!AX29 -> 3 | AY29: ='1'!AY29 -> 912 | AZ29: 2 | BA29: 384 | BB29: =BA29+'1'!BB29 -> 760 | BC29: =BB29/AY29 -> 0.83333333 | BD29: ='1'!BD29 -> 9 | BE29: ='1'!BE29 -> 258 | BF29: 2 | BG29: 52 | BH29: =BG29+'1'!BH29 -> 101 | BI29: =BH29/BE29 -> 0.39147287
A30: 20 | B30: ='1'!B30 -> ميت أبـــــوشيخه | C30: ='1'!C30 -> 1134 | D30: 2 | E30: 1 | F30: =E30+'1'!F30 -> 8 | G30: 10 | H30: =G30+'1'!H30 -> 60 | I30: 147 | J30: =I30+'1'!J30 -> 359 | K30: 0 | L30: =K30+'1'!L30 -> 0 | M30: 0 | N30: =M30+'1'!N30 -> 0 | O30: 0 | P30: =O30+'1'!P30 -> 0 | Q30: =O30+M30+K30+I30+G30+E30 -> 158 | R30: =Q30+'1'!R30 -> 427 | S30: =R30/C30 -> 0.37654321 | T30: 16 | U30: =T30+'1'!U30 -> 43 | V30: 10 | W30: =V30+'1'!W30 -> 10 | X30: 0 | Y30: =X30+'1'!Y30 -> 0 | AB30: 20 | AC30: =AW30 -> ميت أبـــــوشيخه | AD30: ='1'!AI30 -> 73 | AE30: 0 | AF30: =AE30+'1'!AF30 -> 100 | AG30: 16 | AH30: =AG30+'1'!AH30 -> 43 | AI30: =AD30+AE30-AG30 -> 57 | AJ30: =Q30/AG30 -> 9.875 | AK30: =R30/AH30 -> 9.9302326 | AW30: =B30 -> ميت أبـــــوشيخه | AX30: ='1'!AX30 -> 2 | AY30: ='1'!AY30 -> 560 | AZ30: 1 | BA30: 149 | BB30: =BA30+'1'!BB30 -> 399 | BC30: =BB30/AY30 -> 0.7125 | BD30: ='1'!BD30 -> 2 | BE30: ='1'!BE30 -> 107 | BF30: 0 | BG30: 0 | BH30: =BG30+'1'!BH30 -> 0 | BI30: =BH30/BE30 -> 0
A31: 21 | B31: ='1'!B31 -> طــــــــــــه شبرا | C31: ='1'!C31 -> 5149 | D31: 4 | E31: 9 | F31: =E31+'1'!F31 -> 18 | G31: 464 | H31: =G31+'1'!H31 -> 725 | I31: 380 | J31: =I31+'1'!J31 -> 827 | K31: 0 | L31: =K31+'1'!L31 -> 0 | M31: 0 | N31: =M31+'1'!N31 -> 0 | O31: 0 | P31: =O31+'1'!P31 -> 0 | Q31: =O31+M31+K31+I31+G31+E31 -> 853 | R31: =Q31+'1'!R31 -> 1570 | S31: =R31/C31 -> 0.30491358 | T31: 119 | U31: =T31+'1'!U31 -> 194 | V31: 1 | W31: =V31+'1'!W31 -> 3 | X31: 0 | Y31: =X31+'1'!Y31 -> 0 | AB31: 21 | AC31: =AW31 -> طــــــــــــه شبرا | AD31: ='1'!AI31 -> 378 | AE31: 0 | AF31: =AE31+'1'!AF31 -> 452 | AG31: 88 | AH31: =AG31+'1'!AH31 -> 162 | AI31: =AD31+AE31-AG31 -> 290 | AJ31: =Q31/AG31 -> 9.6931818 | AK31: =R31/AH31 -> 9.691358 | AW31: =B31 -> طــــــــــــه شبرا | AX31: ='1'!AX31 -> 6 | AY31: ='1'!AY31 -> 2219 | AZ31: 3 | BA31: 379 | BB31: =BA31+'1'!BB31 -> 933 | BC31: =BB31/AY31 -> 0.42045967 | BD31: ='1'!BD31 -> 8 | BE31: ='1'!BE31 -> 748 | BF31: 6 | BG31: 309 | BH31: =BG31+'1'!BH31 -> 502 | BI31: =BH31/BE31 -> 0.67112299
A32: 22 | B32: ='1'!B32 -> أشـــــــــــــــــليم | C32: ='1'!C32 -> 2638 | D32: 3 | E32: 7 | F32: =E32+'1'!F32 -> 14 | G32: 182 | H32: =G32+'1'!H32 -> 276 | I32: 1030 | J32: =I32+'1'!J32 -> 1428 | K32: 0 | L32: =K32+'1'!L32 -> 0 | M32: 0 | N32: =M32+'1'!N32 -> 0 | O32: 0 | P32: =O32+'1'!P32 -> 0 | Q32: =O32+M32+K32+I32+G32+E32 -> 1219 | R32: =Q32+'1'!R32 -> 1718 | S32: =R32/C32 -> 0.65125095 | T32: 97 | U32: =T32+'1'!U32 -> 142 | V32: 117 | W32: =V32+'1'!W32 -> 117 | X32: 0 | Y32: =X32+'1'!Y32 -> 0 | AB32: 22 | AC32: =AW32 -> أشـــــــــــــــــليم | AD32: ='1'!AI32 -> 180 | AE32: 0 | AF32: =AE32+'1'!AF32 -> 232 | AG32: 125 | AH32: =AG32+'1'!AH32 -> 177 | AI32: =AD32+AE32-AG32 -> 55 | AJ32: =Q32/AG32 -> 9.752 | AK32: =R32/AH32 -> 9.7062147 | AW32: =B32 -> أشـــــــــــــــــليم | AX32: ='1'!AX32 -> 8 | AY32: ='1'!AY32 -> 1819 | AZ32: 4 | BA32: 1037 | BB32: =BA32+'1'!BB32 -> 1469 | BC32: =BB32/AY32 -> 0.80758659 | BD32: ='1'!BD32 -> 7 | BE32: ='1'!BE32 -> 176 | BF32: 6 | BG32: 182 | BH32: =BG32+'1'!BH32 -> 239 | BI32: =BH32/BE32 -> 1.3579545
A33: 23 | B33: ='1'!B33 -> شبرا قبالــــــــــه | C33: ='1'!C33 -> 2050 | D33: 2 | E33: 2 | F33: =E33+'1'!F33 -> 3 | G33: 463 | H33: =G33+'1'!H33 -> 509 | I33: 65 | J33: =I33+'1'!J33 -> 758 | K33: 0 | L33: =K33+'1'!L33 -> 0 | M33: 0 | N33: =M33+'1'!N33 -> 0 | O33: 0 | P33: =O33+'1'!P33 -> 0 | Q33: =O33+M33+K33+I33+G33+E33 -> 530 | R33: =Q33+'1'!R33 -> 1270 | S33: =R33/C33 -> 0.6195122 | T33: 0 | U33: =T33+'1'!U33 -> 96 | V33: 60 | W33: =V33+'1'!W33 -> 64 | X33: 0 | Y33: =X33+'1'!Y33 -> 0 | AB33: 23 | AC33: =AW33 -> شبرا قبالــــــــــه | AD33: ='1'!AI33 -> 106 | AE33: 0 | AF33: =AE33+'1'!AF33 -> 180 | AG33: 53 | AH33: =AG33+'1'!AH33 -> 127 | AI33: =AD33+AE33-AG33 -> 53 | AJ33: =Q33/AG33 -> 10 | AK33: =R33/AH33 -> 10 | AW33: =B33 -> شبرا قبالــــــــــه | AX33: ='1'!AX33 -> 1 | AY33: ='1'!AY33 -> 918 | AZ33: 1 | BA33: 60 | BB33: =BA33+'1'!BB33 -> 780 | BC33: =BB33/AY33 -> 0.8496732 | BD33: ='1'!BD33 -> 5 | BE33: ='1'!BE33 -> 375 | BF33: 6 | BG33: 430 | BH33: =BG33+'1'!BH33 -> 430 | BI33: =BH33/BE33 -> 1.1466667
A34: 24 | B34: ='1'!B34 -> عرب الرمـــــــل | C34: ='1'!C34 -> 5755 | D34: 4 | E34: 9 | F34: =E34+'1'!F34 -> 16 | G34: 373 | H34: =G34+'1'!H34 -> 514 | I34: 437 | J34: =I34+'1'!J34 -> 1057 | K34: 0 | L34: =K34+'1'!L34 -> 0 | M34: 0 | N34: =M34+'1'!N34 -> 0 | O34: 0 | P34: =O34+'1'!P34 -> 0 | Q34: =O34+M34+K34+I34+G34+E34 -> 819 | R34: =Q34+'1'!R34 -> 1587 | S34: =R34/C34 -> 0.27576021 | T34: 204 | U34: =T34+'1'!U34 -> 488 | V34: 41 | W34: =V34+'1'!W34 -> 41 | X34: 0 | Y34: =X34+'1'!Y34 -> 0 | AB34: 24 | AC34: =AW34 -> عرب الرمـــــــل | AD34: ='1'!AI34 -> 427 | AF34: =AE34+'1'!AF34 -> 505 | AG34: 83 | AH34: =AG34+'1'!AH34 -> 161 | AI34: =AD34+AE34-AG34 -> 344 | AJ34: =Q34/AG34 -> 9.8674699 | AK34: =R34/AH34 -> 9.8571429 | AW34: =B34 -> عرب الرمـــــــل | AX34: ='1'!AX34 -> 6 | AY34: ='1'!AY34 -> 2210 | AZ34: 5 | BA34: 509 | BB34: =BA34+'1'!BB34 -> 1146 | BC34: =BB34/AY34 -> 0.51855204 | BD34: ='1'!BD34 -> 9 | BE34: ='1'!BE34 -> 932 | BF34: 4 | BG34: 610 | BH34: =BG34+'1'!BH34 -> 741 | BI34: =BH34/BE34 -> 0.79506438
A35: 25 | B35: ='1'!B35 -> كفر ميت سراج | C35: ='1'!C35 -> 1840 | D35: 2 | E35: 2 | F35: =E35+'1'!F35 -> 4 | G35: 62 | H35: =G35+'1'!H35 -> 121 | I35: 288 | J35: =I35+'1'!J35 -> 587 | K35: 0 | L35: =K35+'1'!L35 -> 0 | M35: 0 | N35: =M35+'1'!N35 -> 0 | O35: 0 | P35: =O35+'1'!P35 -> 0 | Q35: =O35+M35+K35+I35+G35+E35 -> 352 | R35: =Q35+'1'!R35 -> 712 | S35: =R35/C35 -> 0.38695652 | T35: 28 | U35: =T35+'1'!U35 -> 79 | V35: 3 | W35: =V35+'1'!W35 -> 6 | X35: 0 | Y35: =X35+'1'!Y35 -> 0 | AB35: 25 | AC35: =AW35 -> كفر ميت سراج | AD35: ='1'!AI35 -> 126 | AE35: 0 | AF35: =AE35+'1'!AF35 -> 162 | AG35: 38 | AH35: =AG35+'1'!AH35 -> 74 | AI35: =AD35+AE35-AG35 -> 88 | AJ35: =Q35/AG35 -> 9.2631579 | AK35: =R35/AH35 -> 9.6216216 | AW35: =B35 -> كفر ميت سراج | AX35: ='1'!AX35 -> 3 | AY35: ='1'!AY35 -> 1011 | AZ35: 1 | BA35: 276 | BB35: =BA35+'1'!BB35 -> 596 | BC35: =BB35/AY35 -> 0.58951533 | BD35: ='1'!BD35 -> 4 | BE35: ='1'!BE35 -> 413 | BF35: 0 | BG35: 0 | BH35: =BG35+'1'!BH35 -> 0 | BI35: =BH35/BE35 -> 0
A36: 26 | B36: ='1'!B36 -> كفر أبشيش | C36: ='1'!C36 -> 1345 | D36: 2 | E36: 3 | F36: =E36+'1'!F36 -> 6 | G36: 65 | H36: =G36+'1'!H36 -> 123 | I36: 242 | J36: =I36+'1'!J36 -> 547 | K36: 0 | L36: =K36+'1'!L36 -> 0 | M36: 0 | N36: =M36+'1'!N36 -> 0 | O36: 0 | P36: =O36+'1'!P36 -> 0 | Q36: =O36+M36+K36+I36+G36+E36 -> 310 | R36: =Q36+'1'!R36 -> 676 | S36: =R36/C36 -> 0.50260223 | T36: 35 | U36: =T36+'1'!U36 -> 72 | V36: 0 | W36: =V36+'1'!W36 -> 0 | X36: 0 | Y36: =X36+'1'!Y36 -> 0 | AB36: 26 | AC36: =AW36 -> كفر أبشيش | AD36: ='1'!AI36 -> 82 | AE36: 0 | AF36: =AE36+'1'!AF36 -> 119 | AG36: 31 | AH36: =AG36+'1'!AH36 -> 68 | AI36: =AD36+AE36-AG36 -> 51 | AJ36: =Q36/AG36 -> 10 | AK36: =R36/AH36 -> 9.9411765 | AW36: =B36 -> كفر أبشيش | AX36: ='1'!AX36 -> 1 | AY36: ='1'!AY36 -> 860 | AZ36: 1 | BA36: 230 | BB36: =BA36+'1'!BB36 -> 530 | BC36: =BB36/AY36 -> 0.61627907 | BD36: ='1'!BD36 -> 4 | BE36: ='1'!BE36 -> 194 | BF36: 0 | BG36: 0 | BH36: =BG36+'1'!BH36 -> 0 | BI36: =BH36/BE36 -> 0
A37: 27 | B37: ='1'!B37 -> كفر ميت العبسى | C37: ='1'!C37 -> 1180 | D37: 2 | E37: 6 | F37: =E37+'1'!F37 -> 6 | G37: 127 | H37: =G37+'1'!H37 -> 141 | I37: 87 | J37: =I37+'1'!J37 -> 436 | K37: 0 | L37: =K37+'1'!L37 -> 0 | M37: 0 | N37: =M37+'1'!N37 -> 0 | O37: 0 | P37: =O37+'1'!P37 -> 0 | Q37: =O37+M37+K37+I37+G37+E37 -> 220 | R37: =Q37+'1'!R37 -> 583 | S37: =R37/C37 -> 0.4940678 | T37: 13 | U37: =T37+'1'!U37 -> 48 | V37: 8 | W37: =V37+'1'!W37 -> 9 | X37: 0 | Y37: =X37+'1'!Y37 -> 0 | AB37: 27 | AC37: =AW37 -> كفر ميت العبسى | AD37: ='1'!AI37 -> 67 | AE37: 0 | AF37: =AE37+'1'!AF37 -> 104 | AG37: 22 | AH37: =AG37+'1'!AH37 -> 59 | AI37: =AD37+AE37-AG37 -> 45 | AJ37: =Q37/AG37 -> 10 | AK37: =R37/AH37 -> 9.8813559 | AW37: =B37 -> كفر ميت العبسى | AX37: ='1'!AX37 -> 2 | AY37: ='1'!AY37 -> 494 | AZ37: 1 | BA37: 63 | BB37: =BA37+'1'!BB37 -> 416 | BC37: =BB37/AY37 -> 0.84210526 | BD37: ='1'!BD37 -> 4 | BE37: ='1'!BE37 -> 114 | BF37: 2 | BG37: 73 | BH37: =BG37+'1'!BH37 -> 73 | BI37: =BH37/BE37 -> 0.64035088
A38: 28 | B38: ='1'!B38 -> كفر وهــــــــــب | C38: ='1'!C38 -> 1855 | D38: 2 | E38: 2 | F38: =E38+'1'!F38 -> 3 | G38: 66 | H38: =G38+'1'!H38 -> 102 | I38: 246 | J38: =I38+'1'!J38 -> 576 | K38: 0 | L38: =K38+'1'!L38 -> 0 | M38: 0 | N38: =M38+'1'!N38 -> 0 | O38: 0 | P38: =O38+'1'!P38 -> 0 | Q38: =O38+M38+K38+I38+G38+E38 -> 314 | R38: =Q38+'1'!R38 -> 681 | S38: =R38/C38 -> 0.3671159 | T38: 65 | U38: =T38+'1'!U38 -> 112 | V38: 3 | W38: =V38+'1'!W38 -> 4 | X38: 0 | Y38: =X38+'1'!Y38 -> 0 | AB38: 28 | AC38: =AW38 -> كفر وهــــــــــب | AD38: ='1'!AI38 -> 126 | AE38: 0 | AF38: =AE38+'1'!AF38 -> 163 | AG38: 33 | AH38: =AG38+'1'!AH38 -> 70 | AI38: =AD38+AE38-AG38 -> 93 | AJ38: =Q38/AG38 -> 9.5151515 | AK38: =R38/AH38 -> 9.7285714 | AW38: =B38 -> كفر وهــــــــــب | AX38: ='1'!AX38 -> 2 | AY38: ='1'!AY38 -> 793 | AZ38: 2 | BA38: 283 | BB38: =BA38+'1'!BB38 -> 623 | BC38: =BB38/AY38 -> 0.78562421 | BD38: ='1'!BD38 -> 3 | BE38: ='1'!BE38 -> 180 | BF38: 0 | BG38: 0 | BH38: =BG38+'1'!BH38 -> 0 | BI38: =BH38/BE38 -> 0
A39: 29 | B39: ='1'!B39 -> دمــــــــــــــهوج | C39: ='1'!C39 -> 2738 | D39: 3 | E39: 0 | F39: =E39+'1'!F39 -> 1 | G39: 96 | H39: =G39+'1'!H39 -> 141 | I39: 305 | J39: =I39+'1'!J39 -> 829 | K39: 0 | L39: =K39+'1'!L39 -> 0 | M39: 0 | N39: =M39+'1'!N39 -> 0 | O39: 0 | P39: =O39+'1'!P39 -> 0 | Q39: =O39+M39+K39+I39+G39+E39 -> 401 | R39: =Q39+'1'!R39 -> 971 | S39: =R39/C39 -> 0.35463842 | T39: 73 | U39: =T39+'1'!U39 -> 138 | V39: 3 | W39: =V39+'1'!W39 -> 3 | X39: 0 | Y39: =X39+'1'!Y39 -> 0 | AB39: 29 | AC39: =AW39 -> دمــــــــــــــهوج | AD39: ='1'!AI39 -> 182 | AE39: 0 | AF39: =AE39+'1'!AF39 -> 240 | AG39: 41 | AH39: =AG39+'1'!AH39 -> 99 | AI39: =AD39+AE39-AG39 -> 141 | AJ39: =Q39/AG39 -> 9.7804878 | AK39: =R39/AH39 -> 9.8080808 | AW39: =B39 -> دمــــــــــــــهوج | AX39: ='1'!AX39 -> 2 | AY39: ='1'!AY39 -> 1086 | AZ39: 1 | BA39: 304 | BB39: =BA39+'1'!BB39 -> 834 | BC39: =BB39/AY39 -> 0.7679558 | BD39: ='1'!BD39 -> 10 | BE39: ='1'!BE39 -> 455 | BF39: 2 | BG39: 90 | BH39: =BG39+'1'!BH39 -> 130 | BI39: =BH39/BE39 -> 0.28571429
A40: 30 | B40: ='1'!B40 -> كفر زين الدين | C40: ='1'!C40 -> 819 | D40: 2 | E40: 1 | F40: =E40+'1'!F40 -> 6 | G40: 135 | H40: =G40+'1'!H40 -> 208 | I40: 164 | J40: =I40+'1'!J40 -> 416 | K40: 0 | L40: =K40+'1'!L40 -> 0 | M40: 0 | N40: =M40+'1'!N40 -> 0 | O40: 0 | P40: =O40+'1'!P40 -> 0 | Q40: =O40+M40+K40+I40+G40+E40 -> 300 | R40: =Q40+'1'!R40 -> 630 | S40: =R40/C40 -> 0.76923077 | T40: 38 | U40: =T40+'1'!U40 -> 76 | V40: 9 | W40: =V40+'1'!W40 -> 16 | X40: 0 | Y40: =X40+'1'!Y40 -> 0 | AB40: 30 | AC40: =AW40 -> كفر زين الدين | AD40: ='1'!AI40 -> 37 | AE40: 0 | AF40: =AE40+'1'!AF40 -> 70 | AG40: 30 | AH40: =AG40+'1'!AH40 -> 63 | AI40: =AD40+AE40-AG40 -> 7 | AJ40: =Q40/AG40 -> 10 | AK40: =R40/AH40 -> 10 | AW40: =B40 -> كفر زين الدين | AX40: ='1'!AX40 -> 1 | AY40: ='1'!AY40 -> 563 | AZ40: 1 | BA40: 154 | BB40: =BA40+'1'!BB40 -> 354 | BC40: =BB40/AY40 -> 0.62877442 | BD40: ='1'!BD40 -> 2 | BE40: ='1'!BE40 -> 87 | BF40: 3 | BG40: 96 | BH40: =BG40+'1'!BH40 -> 166 | BI40: =BH40/BE40 -> 1.908046
...

Sheet 3
A1: وزارة الصحة والسكان | AB1: وزارة الصحة والسكان | AW1: وزارة الصحة والسكان
A2: قطاع الطب الوقائي والصحة العامة | AB2: قطاع الطب الوقائي والصحة العامة | AW2: قطاع الطب الوقائي والصحة العامة
A3: الإدارة المركزية للصحة العامة | AB3: الإدارة المركزية للصحة العامة | AW3: الإدارة المركزية للصحة العامة
A4: الإدارة العامة لمكافحة الأمراض المعدية | AB4: الإدارة العامة لمكافحة الأمراض المعدية | AW4: الإدارة العامة لمكافحة الأمراض المعدية
A5: البرنامج الموسع للتطعيمات | AB5: البرنامج الموسع للتطعيمات | AW5: البرنامج الموسع للتطعيمات
A6: بيان باعداد المتطعمين و المتغيبين و الاثار الجانبية بالحملة القومية للتطعيم بطعم MR | AF6: البلاغ اليومى لحركة الطعوم بالحملة القومية للتطعيم بطعم MR | AY6: بيان المدارس و الحضانات بالحملة القومية للتطعيم بطعم MR
A7: مديرية الشئون الصحية / المنوفية الإدارة الصحية / قويسنا التاريخ / 27\10\2026 اليوم /الثلاثاء | AJ7: مديرية الشئون الصحية / الإدارة الصحية / التاريخ/ اليوم / | BC7: مديرية الشئون الصحية / الإدارة الصحية / التاريخ/ اليوم /
A8: م | B8: اسم الوحدة/ مكتب الصحة | C8: المستهدف | D8: عدد الفرق | E8: المتطعمين المصريين | K8: المتطعمين غير المصريين | Q8: الاجمالى | S8: النسبة | T8: المتغيبين عن التطعيم | V8: المطعمين من المتغيبين | X8: الاثار الجانبية | AB8: م | AC8: اسم الوحدة | AD8: الرصيد اول اليوم | AE8: عدد الزجاجات الواردة | AG8: عدد الزجاجات المستهلكة | AI8: عدد الزجاجات المتبقية | AJ8: معدل الزجاجة اليوم | AK8: معدل الزجاجة حتي اليوم | AM8: مخزن طعوم الادارة | AN8: التشغيلة | AO8: الرصيد اول اليوم | AP8: عدد الزجاجات الواردة | AR8: عدد الزجاجات المنصرفة | AT8: عدد الزجاجات المتبقية | AW8: اسم الوحدة | AX8: بيان المدارس | BD8: بيان الحضانات
E9: من 9 شهور لأقل من عام | G9: من عام لأقل من5 سنوات | I9: من 5 سنوات الى 10 سنة | K9: من 9 شهور لأقل من عام | M9: من عام لأقل من5 سنوات | O9: من 5 سنوات الى 10 سنة | AP9: اليوم | AQ9: حتى اليوم | AR9: اليوم | AS9: حتى اليوم | AX9: عدد المدارس | AY9: المستهدف | AZ9: عدد المدارس التي تم زيارتها حتى اليوم | BA9: عدد المتطعمين اليوم | BB9: عدد المتطعمين حتى اليوم | BC9: النسبة | BD9: عدد الحضانات | BE9: المستهدف | BF9: عدد الحضانات التي تم زيارتها حتى اليوم | BG9: عدد المتطعمين اليوم | BH9: عدد المتطعمين حتى اليوم | BI9: النسبة
E10: اليوم | F10: حتى اليوم | G10: اليوم | H10: حتى اليوم | I10: اليوم | J10: حتى اليوم | K10: اليوم | L10: حتى اليوم | M10: اليوم | N10: حتى اليوم | O10: اليوم | P10: حتى اليوم | Q10: اليوم | R10: حتى اليوم | T10: اليوم | U10: حتى اليوم | V10: اليوم | W10: حتى اليوم | X10: اليوم | Y10: حتى اليوم | AE10: اليوم | AF10: حتى اليوم | AG10: اليوم | AH10: حتى اليوم | AN10: ='2'!AN10 -> 0124W120 | AO10: ='2'!AT10 -> 73 | AP10: 0 | AQ10: =AP10+'2'!AQ10 -> 73 | AR10: 25 | AS10: =AR10+'2'!AS10 -> 25 | AT10: =AO10+AP10-AR10 -> 48
A11: 1 | B11: ='2'!B11 -> مكتب الصحة | C11: ='2'!C11 -> 12251 | D11: 13 | E11: 16 | F11: =E11+'2'!F11 -> 39 | G11: 887 | H11: =G11+'2'!H11 -> 1961 | I11: 1605 | J11: =I11+'2'!J11 -> 5340 | K11: 0 | L11: =K11+'2'!L11 -> 0 | M11: 0 | N11: =M11+'2'!N11 -> 0 | O11: 0 | P11: =O11+'2'!P11 -> 0 | Q11: =O11+M11+K11+I11+G11+E11 -> 2508 | R11: =Q11+'2'!R11 -> 7340 | S11: =R11/C11 -> 0.59913476 | T11: 463 | U11: =T11+'2'!U11 -> 1397 | V11: 4 | W11: =V11+'2'!W11 -> 4 | X11: 1 | Y11: =X11+'2'!Y11 -> 1 | AB11: 1 | AC11: ='2'!AC11 -> مكتب الصحة | AD11: ='2'!AI11 -> 584 | AE11: 6 | AF11: =AE11+'2'!AF11 -> 1082 | AG11: 257 | AH11: =AG11+'2'!AH11 -> 749 | AI11: =AD11+AE11-AG11 -> 333 | AJ11: =Q11/AG11 -> 9.7587549 | AK11: =R11/AH11 -> 9.799733 | AN11: ='2'!AN11 -> 420604325A | AO11: ='2'!AT11 -> 4499 | AQ11: =AP11+'2'!AQ11 -> 8550 | AR11: 1423 | AS11: =AR11+'2'!AS11 -> 5474 | AT11: =AO11+AP11-AR11 -> 3076 | AW11: ='2'!AW11 -> مكتب الصحة | AX11: ='2'!AX11 -> 11 | AY11: ='2'!AY11 -> 8411 | AZ11: 11 | BA11: 1822 | BB11: =BA11+'2'!BB11 -> 5998 | BC11: =BB11/AY11 -> 0.71311378 | BD11: ='2'!BD11 -> 27 | BE11: ='2'!BE11 -> 1746 | BF11: 13 | BG11: 346 | BH11: =BG11+'2'!BH11 -> 477 | BI11: =BH11/BE11 -> 0.27319588
